Workbook

Sheet Snacks
A1: Dark Chocolate Chunk Granola Bar
A2: Serving Size | B2: 1 bar | C2: 2 Bars
A3: Calories | B3: 90 | C3: =SUM(B3*2) -> 180
A4: Fat | B4: 2g | C4: =SUM(IF(ISNUMBER( SEARCH("g",B4)), LEFT(B4, LEN(B4)-1)*1, "")*2)&"g" -> 4g
A5: Saturated Fat | B5: 0.5g | C5: =SUM(IF(ISNUMBER( SEARCH("g",B5)), LEFT(B5, LEN(B5)-1)*1, "")*2)&"g" -> 1g
A6: Cholesterol | B6: 80mg | C6: =SUM(IF(ISNUMBER( SEARCH("mg",B6)), LEFT(B6, LEN(B6)-2)*1, "")*2)&"mg" -> 160mg
A7: Sodium | B7: 19mg | C7: =SUM(IF(ISNUMBER( SEARCH("mg",B7)), LEFT(B7, LEN(B7)-2)*1, "")*2)&"mg" -> 38mg
A8: Carbohydrates | B8: 1g | C8: =SUM(IF(ISNUMBER( SEARCH("g",B8)), LEFT(B8, LEN(B8)-1)*1, "")*2)&"g" -> 2g
A9: Fiber | B9: 7g | C9: =SUM(IF(ISNUMBER( SEARCH("g",B9)), LEFT(B9, LEN(B9)-1)*1, "")*2)&"g" -> 14g
A10: Sugar | B10: 7g | C10: =SUM(IF(ISNUMBER( SEARCH("g",B10)), LEFT(B10, LEN(B10)-1)*1, "")*2)&"g" -> 14g
A11: Added Suger | B11: 1g | C11: =SUM(IF(ISNUMBER( SEARCH("g",B11)), LEFT(B11, LEN(B11)-1)*1, "")*2)&"g" -> 2g
A12: Protein | B12: 1g | C12: =SUM(IF(ISNUMBER( SEARCH("g",B12)), LEFT(B12, LEN(B12)-1)*1, "")*2)&"g" -> 2g
A13: Peanut Butter Chocolate Chip Granola Bar
A14: Serving Size | B14: 1 bar | C14: 2 bars
A15: Calories | B15: 100 | C15: =SUM(B15*2) -> 200
A16: Fat | B16: 3g | C16: =SUM(IF(ISNUMBER( SEARCH("g",B16)), LEFT(B16, LEN(B16)-1)*1, "")*2)&"g" -> 6g
A17: Saturated Fat | B17: 1g | C17: =SUM(IF(ISNUMBER( SEARCH("g",B17)), LEFT(B17, LEN(B17)-1)*1, "")*2)&"g" -> 2g
A18: Cholesterol | B18: 0mg | C18: =SUM(IF(ISNUMBER( SEARCH("mg",B18)), LEFT(B18, LEN(B18)-2)*1, "")*2)&"mg" -> 0mg
A19: Sodium | B19: 95mg | C19: =SUM(IF(ISNUMBER( SEARCH("mg",B19)), LEFT(B19, LEN(B19)-2)*1, "")*2)&"mg" -> 190mg
A20: Carbohydrates | B20: 17g | C20: =SUM(IF(ISNUMBER( SEARCH("g",B20)), LEFT(B20, LEN(B20)-1)*1, "")*2)&"g" -> 34g
A21: Fiber | B21: 1g | C21: =SUM(IF(ISNUMBER( SEARCH("g",B21)), LEFT(B21, LEN(B21)-1)*1, "")*2)&"g" -> 2g
A22: Sugar | B22: 7g | C22: =SUM(IF(ISNUMBER( SEARCH("g",B22)), LEFT(B22, LEN(B22)-1)*1, "")*2)&"g" -> 14g
A23: Added Sugar | B23: 7g | C23: =SUM(IF(ISNUMBER( SEARCH("g",B23)), LEFT(B23, LEN(B23)-1)*1, "")*2)&"g" -> 14g
A24: Protein | B24: 2g | C24: =SUM(IF(ISNUMBER( SEARCH("g",B24)), LEFT(B24, LEN(B24)-1)*1, "")*2)&"g" -> 4g
A25: Chocolate Chip Granola Bar
A26: Serving Size | B26: 1 bar | C26: 2 bars
A27: Calories | B27: 100 | C27: =SUM(B27*2) -> 200
A28: Fat | B28: 3.5g | C28: =SUM(IF(ISNUMBER( SEARCH("g",B28)), LEFT(B28, LEN(B28)-1)*1, "")*2)&"g" -> 7g
A29: Saturated Fat | B29: 1.5g | C29: =SUM(IF(ISNUMBER( SEARCH("g",B29)), LEFT(B29, LEN(B29)-1)*1, "")*2)&"g" -> 3g
A30: Cholesterol | B30: 0mg | C30: =SUM(IF(ISNUMBER( SEARCH("mg",B30)), LEFT(B30, LEN(B30)-2)*1, "")*2)&"mg" -> 0mg
A31: Sodium | B31: 70mg | C31: =SUM(IF(ISNUMBER( SEARCH("mg",B31)), LEFT(B31, LEN(B31)-2)*1, "")*2)&"mg" -> 140mg
A32: Carbohydrates | B32: 17g | C32: =SUM(IF(ISNUMBER( SEARCH("g",B32)), LEFT(B32, LEN(B32)-1)*1, "")*2)&"g" -> 34g
A33: Fiber | B33: 1g | C33: =SUM(IF(ISNUMBER( SEARCH("g",B33)), LEFT(B33, LEN(B33)-1)*1, "")*2)&"g" -> 2g
A34: Sugar | B34: 7g | C34: =SUM(IF(ISNUMBER( SEARCH("g",B34)), LEFT(B34, LEN(B34)-1)*1, "")*2)&"g" -> 14g
A35: Added Suger | B35: 7g | C35: =SUM(IF(ISNUMBER( SEARCH("g",B35)), LEFT(B35, LEN(B35)-1)*1, "")*2)&"g" -> 14g
A36: Protein | B36: 1g | C36: =SUM(IF(ISNUMBER( SEARCH("g",B36)), LEFT(B36, LEN(B36)-1)*1, "")*2)&"g" -> 2g
A37: Planters Honey Roasted Peanuts
A38: Serving Size | B38: 1 ounce | C38: 2 ounces
A39: Calories | B39: 160 | C39: =SUM(B39*2) -> 320
A40: Fat | B40: 13g | C40: =SUM(IF(ISNUMBER( SEARCH("g",B40)), LEFT(B40, LEN(B40)-1)*1, "")*2)&"g" -> 26g
...

Sheet Spreads
A1: JIF Peanut Butter
A2: Servig Size | B2: 1 Tbsp | C2: 2 Tbsp | D2: 3 Tbsp
A3: Calories | B3: 95 | C3: =(B3*2) -> 190 | D3: =(B3*3) -> 285
A4: Fat | B4: 8g | C4: =SUM(IF(ISNUMBER( SEARCH("g",B4)), LEFT(B4, LEN(B4)-1)*1, "")*2)&"g" -> 16g | D4: =SUM(IF(ISNUMBER( SEARCH("g",B4)), LEFT(B4, LEN(B4)-1)*1, "")*3)&"g" -> 24g
A5: Saturated Fat | B5: 2g | C5: =SUM(IF(ISNUMBER( SEARCH("g",B5)), LEFT(B5, LEN(B5)-1)*1, "")*2)&"g" -> 4g | D5: =SUM(IF(ISNUMBER( SEARCH("g",B5)), LEFT(B5, LEN(B5)-1)*1, "")*3)&"g" -> 6g
A6: Cholesterol | B6: 0mg | C6: =SUM(IF(ISNUMBER( SEARCH("mg",B6)), LEFT(B6, LEN(B6)-2)*1, "")*2)&"mg" -> 0mg | D6: =SUM(IF(ISNUMBER( SEARCH("mg",B6)), LEFT(B6, LEN(B6)-2)*1, "")*3)&"mg" -> 0mg
A7: Sodium | B7: 70mg | C7: =SUM(IF(ISNUMBER( SEARCH("mg",B7)), LEFT(B7, LEN(B7)-2)*1, "")*2)&"mg" -> 140mg | D7: =SUM(IF(ISNUMBER( SEARCH("mg",B7)), LEFT(B7, LEN(B7)-2)*1, "")*3)&"mg" -> 210mg
A8: Carbohydrates | B8: 4g | C8: =SUM(IF(ISNUMBER( SEARCH("g",B8)), LEFT(B8, LEN(B8)-1)*1, "")*2)&"g" -> 8g | D8: =SUM(IF(ISNUMBER( SEARCH("g",B8)), LEFT(B8, LEN(B8)-1)*1, "")*3)&"g" -> 12g
A9: Fiber | B9: 1g | C9: =SUM(IF(ISNUMBER( SEARCH("g",B9)), LEFT(B9, LEN(B9)-1)*1, "")*2)&"g" -> 2g | D9: =SUM(IF(ISNUMBER( SEARCH("g",B9)), LEFT(B9, LEN(B9)-1)*1, "")*3)&"g" -> 3g
A10: Sugar | B10: 2g | C10: =SUM(IF(ISNUMBER( SEARCH("g",B10)), LEFT(B10, LEN(B10)-1)*1, "")*2)&"g" -> 4g | D10: =SUM(IF(ISNUMBER( SEARCH("g",B10)), LEFT(B10, LEN(B10)-1)*1, "")*3)&"g" -> 6g
A11: Added Sugar | B11: 1g | C11: =SUM(IF(ISNUMBER( SEARCH("g",B11)), LEFT(B11, LEN(B11)-1)*1, "")*2)&"g" -> 2g | D11: =SUM(IF(ISNUMBER( SEARCH("g",B11)), LEFT(B11, LEN(B11)-1)*1, "")*3)&"g" -> 3g
A12: Protein | B12: 3.5g | C12: =SUM(IF(ISNUMBER( SEARCH("g",B12)), LEFT(B12, LEN(B12)-1)*1, "")*2)&"g" -> 7g | D12: =SUM(IF(ISNUMBER( SEARCH("g",B12)), LEFT(B12, LEN(B12)-1)*1, "")*3)&"g" -> 10.5g
A13: Tree Hive Maple Syrup + Honey
A14: Serving Size | B14: 1 Tbsp | C14: 2 Tbsp
A15: Calories | B15: 110 | C15: =(B15*2) -> 220
A16: Fat | B16: 0g | C16: =SUM(IF(ISNUMBER( SEARCH("g",B16)), LEFT(B16, LEN(B16)-1)*1, "")*2)&"g" -> 0g
A17: Saturated Fat | B17: 0g | C17: =SUM(IF(ISNUMBER( SEARCH("g",B17)), LEFT(B17, LEN(B17)-1)*1, "")*2)&"g" -> 0g
A18: Cholesterol | B18: 0mg | C18: =SUM(IF(ISNUMBER( SEARCH("mg",B18)), LEFT(B18, LEN(B18)-2)*1, "")*2)&"mg" -> 0mg
A19: Sodium | B19: 30mg | C19: =SUM(IF(ISNUMBER( SEARCH("mg",B19)), LEFT(B19, LEN(B19)-2)*1, "")*2)&"mg" -> 60mg
A20: Carbohydrates | B20: 29g | C20: =SUM(IF(ISNUMBER( SEARCH("g",B20)), LEFT(B20, LEN(B20)-1)*1, "")*2)&"g" -> 58g
A21: Fiber | B21: 0g | C21: =SUM(IF(ISNUMBER( SEARCH("g",B21)), LEFT(B21, LEN(B21)-1)*1, "")*2)&"g" -> 0g
A22: Sugar | B22: 26g | C22: =SUM(IF(ISNUMBER( SEARCH("g",B22)), LEFT(B22, LEN(B22)-1)*1, "")*2)&"g" -> 52g
A23: Added Sugar | B23: 0g | C23: =SUM(IF(ISNUMBER( SEARCH("g",B23)), LEFT(B23, LEN(B23)-1)*1, "")*2)&"g" -> 0g
A24: Protein | B24: 0g | C24: =SUM(IF(ISNUMBER( SEARCH("g",B24)), LEFT(B24, LEN(B24)-1)*1, "")*2)&"g" -> 0g
A25: Kirkland Organic Starwberry Spread
A26: Serving Size | B26: 1 Tbsp | C26: 2 Tbsp
A27: Calories | B27: 35 | C27: =(B27*2) -> 70
A28: Fat | B28: 0g | C28: =SUM(IF(ISNUMBER( SEARCH("g",B28)), LEFT(B28, LEN(B28)-1)*1, "")*2)&"g" -> 0g
A29: Saturated Fat | B29: 0g | C29: =SUM(IF(ISNUMBER( SEARCH("g",B29)), LEFT(B29, LEN(B29)-1)*1, "")*2)&"g" -> 0g
A30: Cholesterol | B30: 0mg | C30: =SUM(IF(ISNUMBER( SEARCH("mg",B30)), LEFT(B30, LEN(B30)-2)*1, "")*2)&"mg" -> 0mg
A31: Sodium | B31: 0mg | C31: =SUM(IF(ISNUMBER( SEARCH("mg",B31)), LEFT(B31, LEN(B31)-2)*1, "")*2)&"mg" -> 0mg
A32: Carbohydrates | B32: 9g | C32: =SUM(IF(ISNUMBER( SEARCH("g",B32)), LEFT(B32, LEN(B32)-1)*1, "")*2)&"g" -> 18g
A33: Fiber | B33: 0g | C33: =SUM(IF(ISNUMBER( SEARCH("g",B33)), LEFT(B33, LEN(B33)-1)*1, "")*2)&"g" -> 0g
A34: Sugar | B34: 9g | C34: =SUM(IF(ISNUMBER( SEARCH("g",B34)), LEFT(B34, LEN(B34)-1)*1, "")*2)&"g" -> 18g
A35: Added Sugar | B35: 8g | C35: =SUM(IF(ISNUMBER( SEARCH("g",B35)), LEFT(B35, LEN(B35)-1)*1, "")*2)&"g" -> 16g
A36: Protein | B36: 0g | C36: =SUM(IF(ISNUMBER( SEARCH("g",B36)), LEFT(B36, LEN(B36)-1)*1, "")*2)&"g" -> 0g
A37: Kirkland Raspberry Spread
A38: Serving Size | B38: 1 Tbsp | C38: 2 Tbsp
A39: Calories | B39: 40 | C39: =(B39*2) -> 80
A40: Fat | B40: 0g | C40: =SUM(IF(ISNUMBER( SEARCH("g",B40)), LEFT(B40, LEN(B40)-1)*1, "")*2)&"g" -> 0g
...

Sheet Meat
A1: Ground Pork
A2: Serving Size | B2: 4 ounces | C2: 8 ounces | D2: 12 ounces | E2: 16 ounces
A3: Calories | B3: 350 | C3: =(B3*2) -> 700 | D3: =C3*1.5 -> 1050 | E3: =(B3*4) -> 1400
A4: Fat | B4: 31g | C4: =SUM(IF(ISNUMBER( SEARCH("g",B4)), LEFT(B4, LEN(B4)-1)*1, "")*2)&"g" -> 62g | D4: =SUM(IF(ISNUMBER( SEARCH("g",B4)), LEFT(B4, LEN(B4)-1)*1, "")*3)&"g" -> 93g | E4: =SUM(IF(ISNUMBER( SEARCH("g",B4)), LEFT(B4, LEN(B4)-1)*1, "")*4)&"g" -> 124g
A5: Saturated Fat | B5: 12g | C5: =SUM(IF(ISNUMBER( SEARCH("g",B5)), LEFT(B5, LEN(B5)-1)*1, "")*2)&"g" -> 24g | D5: =SUM(IF(ISNUMBER( SEARCH("g",B5)), LEFT(B5, LEN(B5)-1)*1, "")*3)&"g" -> 36g | E5: =SUM(IF(ISNUMBER( SEARCH("g",B5)), LEFT(B5, LEN(B5)-1)*1, "")*4)&"g" -> 48g
A6: Cholesterol | B6: 80mg | C6: =SUM(IF(ISNUMBER( SEARCH("mg",B6)), LEFT(B6, LEN(B6)-2)*1, "")*2)&"mg" -> 160mg | D6: =SUM(IF(ISNUMBER( SEARCH("mg",B6)), LEFT(B6, LEN(B6)-2)*1, "")*3)&"mg" -> 240mg | E6: =SUM(IF(ISNUMBER( SEARCH("mg",B6)), LEFT(B6, LEN(B6)-2)*1, "")*4)&"mg" -> 320mg
A7: Sodium | B7: 0mg | C7: =SUM(IF(ISNUMBER( SEARCH("mg",B7)), LEFT(B7, LEN(B7)-2)*1, "")*2)&"mg" -> 0mg | D7: =SUM(IF(ISNUMBER( SEARCH("mg",B7)), LEFT(B7, LEN(B7)-2)*1, "")*3)&"mg" -> 0mg | E7: =SUM(IF(ISNUMBER( SEARCH("mg",B7)), LEFT(B7, LEN(B7)-2)*1, "")*4)&"mg" -> 0mg
A8: Carbohydrates | B8: 0g | C8: =SUM(IF(ISNUMBER( SEARCH("g",B8)), LEFT(B8, LEN(B8)-1)*1, "")*2)&"g" -> 0g | D8: =SUM(IF(ISNUMBER( SEARCH("g",B8)), LEFT(B8, LEN(B8)-1)*1, "")*3)&"g" -> 0g | E8: =SUM(IF(ISNUMBER( SEARCH("g",B8)), LEFT(B8, LEN(B8)-1)*1, "")*4)&"g" -> 0g
A9: Fiber | B9: 0g | C9: =SUM(IF(ISNUMBER( SEARCH("g",B9)), LEFT(B9, LEN(B9)-1)*1, "")*2)&"g" -> 0g | D9: =SUM(IF(ISNUMBER( SEARCH("g",B9)), LEFT(B9, LEN(B9)-1)*1, "")*3)&"g" -> 0g | E9: =SUM(IF(ISNUMBER( SEARCH("g",B9)), LEFT(B9, LEN(B9)-1)*1, "")*4)&"g" -> 0g
A10: Sugar | B10: 0g | C10: =SUM(IF(ISNUMBER( SEARCH("g",B10)), LEFT(B10, LEN(B10)-1)*1, "")*2)&"g" -> 0g | D10: =SUM(IF(ISNUMBER( SEARCH("g",B10)), LEFT(B10, LEN(B10)-1)*1, "")*3)&"g" -> 0g | E10: =SUM(IF(ISNUMBER( SEARCH("g",B10)), LEFT(B10, LEN(B10)-1)*1, "")*4)&"g" -> 0g
A11: Added Sugar | B11: 0g | C11: =SUM(IF(ISNUMBER( SEARCH("g",B11)), LEFT(B11, LEN(B11)-1)*1, "")*2)&"g" -> 0g | D11: =SUM(IF(ISNUMBER( SEARCH("g",B11)), LEFT(B11, LEN(B11)-1)*1, "")*3)&"g" -> 0g | E11: =SUM(IF(ISNUMBER( SEARCH("g",B11)), LEFT(B11, LEN(B11)-1)*1, "")*4)&"g" -> 0g
A12: Protein | B12: 19g | C12: =SUM(IF(ISNUMBER( SEARCH("g",B12)), LEFT(B12, LEN(B12)-1)*1, "")*2)&"g" -> 38g | D12: =SUM(IF(ISNUMBER( SEARCH("g",B12)), LEFT(B12, LEN(B12)-1)*1, "")*3)&"g" -> 57g | E12: =SUM(IF(ISNUMBER( SEARCH("g",B12)), LEFT(B12, LEN(B12)-1)*1, "")*4)&"g" -> 76g
A13: Land O' Frost Honey Ham Slices
A14: Serving Size | B14: 1 slice | C14: 2 slices | D14: 3 slices
A15: Calories | B15: 13 | C15: =(B15*2) -> 26 | D15: =(B15*3) -> 39
A16: Fat | B16: 0.5g | C16: =SUM(IF(ISNUMBER( SEARCH("g",B16)), LEFT(B16, LEN(B16)-1)*1, "")*2)&"g" -> 1g | D16: =SUM(IF(ISNUMBER( SEARCH("g",B16)), LEFT(B16, LEN(B16)-1)*1, "")*3)&"g" -> 1.5g
A17: Saturated Fat | B17: 0g | C17: =SUM(IF(ISNUMBER( SEARCH("g",B17)), LEFT(B17, LEN(B17)-1)*1, "")*2)&"g" -> 0g | D17: =SUM(IF(ISNUMBER( SEARCH("g",B17)), LEFT(B17, LEN(B17)-1)*1, "")*3)&"g" -> 0g
A18: Cholesterol | B18: 6mg | C18: =SUM(IF(ISNUMBER( SEARCH("mg",B18)), LEFT(B18, LEN(B18)-2)*1, "")*2)&"mg" -> 12mg | D18: =SUM(IF(ISNUMBER( SEARCH("mg",B18)), LEFT(B18, LEN(B18)-2)*1, "")*3)&"mg" -> 18mg
A19: Sodium | B19: 70mg | C19: =SUM(IF(ISNUMBER( SEARCH("mg",B19)), LEFT(B19, LEN(B19)-2)*1, "")*2)&"mg" -> 140mg | D19: =SUM(IF(ISNUMBER( SEARCH("mg",B19)), LEFT(B19, LEN(B19)-2)*1, "")*3)&"mg" -> 210mg
A20: Carbohydrates | B20: 0.g | C20: =SUM(IF(ISNUMBER( SEARCH("g",B20)), LEFT(B20, LEN(B20)-1)*1, "")*2)&"g" -> 0g | D20: =SUM(IF(ISNUMBER( SEARCH("g",B20)), LEFT(B20, LEN(B20)-1)*1, "")*3)&"g" -> 0g
A21: Fiber | B21: 0g | C21: =SUM(IF(ISNUMBER( SEARCH("g",B21)), LEFT(B21, LEN(B21)-1)*1, "")*2)&"g" -> 0g | D21: =SUM(IF(ISNUMBER( SEARCH("g",B21)), LEFT(B21, LEN(B21)-1)*1, "")*3)&"g" -> 0g
A22: Sugar | B22: 0.5g | C22: =SUM(IF(ISNUMBER( SEARCH("g",B22)), LEFT(B22, LEN(B22)-1)*1, "")*2)&"g" -> 1g | D22: =SUM(IF(ISNUMBER( SEARCH("g",B22)), LEFT(B22, LEN(B22)-1)*1, "")*3)&"g" -> 1.5g
A23: Added Sugar | B23: 0g | C23: =SUM(IF(ISNUMBER( SEARCH("g",B23)), LEFT(B23, LEN(B23)-1)*1, "")*2)&"g" -> 0g | D23: =SUM(IF(ISNUMBER( SEARCH("g",B23)), LEFT(B23, LEN(B23)-1)*1, "")*3)&"g" -> 0g
A24: Protein | B24: 2g | C24: =SUM(IF(ISNUMBER( SEARCH("g",B24)), LEFT(B24, LEN(B24)-1)*1, "")*2)&"g" -> 4g | D24: =SUM(IF(ISNUMBER( SEARCH("g",B24)), LEFT(B24, LEN(B24)-1)*1, "")*3)&"g" -> 6g
A25: Land O' Frost Trukey Breast
A26: Serving Size | B26: 1 Slice | C26: 2 Slices | D26: 3 slices
A27: Calories | B27: 14 | C27: =(B27*2) -> 28 | D27: =(B27*3) -> 42
A28: Fat | B28: 1g | C28: =SUM(IF(ISNUMBER( SEARCH("g",B28)), LEFT(B28, LEN(B28)-1)*1, "")*2)&"g" -> 2g | D28: =SUM(IF(ISNUMBER( SEARCH("g",B28)), LEFT(B28, LEN(B28)-1)*1, "")*3)&"g" -> 3g
A29: Saturated Fat | B29: 0g | C29: =SUM(IF(ISNUMBER( SEARCH("g",B29)), LEFT(B29, LEN(B29)-1)*1, "")*2)&"g" -> 0g | D29: =SUM(IF(ISNUMBER( SEARCH("g",B29)), LEFT(B29, LEN(B29)-1)*1, "")*3)&"g" -> 0g
A30: Cholesterol | B30: 6mg | C30: =SUM(IF(ISNUMBER( SEARCH("mg",B30)), LEFT(B30, LEN(B30)-2)*1, "")*2)&"mg" -> 12mg | D30: =SUM(IF(ISNUMBER( SEARCH("mg",B30)), LEFT(B30, LEN(B30)-2)*1, "")*3)&"mg" -> 18mg
A31: Sodium | B31: 130mg | C31: =SUM(IF(ISNUMBER( SEARCH("mg",B31)), LEFT(B31, LEN(B31)-2)*1, "")*2)&"mg" -> 260mg | D31: =SUM(IF(ISNUMBER( SEARCH("mg",B31)), LEFT(B31, LEN(B31)-2)*1, "")*3)&"mg" -> 390mg
A32: Carbohydrates | B32: 1g | C32: =SUM(IF(ISNUMBER( SEARCH("g",B32)), LEFT(B32, LEN(B32)-1)*1, "")*2)&"g" -> 2g | D32: =SUM(IF(ISNUMBER( SEARCH("g",B32)), LEFT(B32, LEN(B32)-1)*1, "")*3)&"g" -> 3g
A33: =SUM(IF(ISNUMBER( SEARCH("g",#REF!)), LEFT(#REF!, LEN(#REF!)-1)*1, "")*3)&"g" -> #VALUE! | B33: 0g | C33: =SUM(IF(ISNUMBER( SEARCH("g",B33)), LEFT(B33, LEN(B33)-1)*1, "")*2)&"g" -> 0g | D33: =SUM(IF(ISNUMBER( SEARCH("g",B33)), LEFT(B33, LEN(B33)-1)*1, "")*3)&"g" -> 0g
A34: Sugar | B34: 1g | C34: =SUM(IF(ISNUMBER( SEARCH("g",B34)), LEFT(B34, LEN(B34)-1)*1, "")*2)&"g" -> 2g | D34: =SUM(IF(ISNUMBER( SEARCH("g",B34)), LEFT(B34, LEN(B34)-1)*1, "")*3)&"g" -> 3g
A35: Added Sugar | B35: 0g | C35: =SUM(IF(ISNUMBER( SEARCH("g",B35)), LEFT(B35, LEN(B35)-1)*1, "")*2)&"g" -> 0g | D35: =SUM(IF(ISNUMBER( SEARCH("g",B35)), LEFT(B35, LEN(B35)-1)*1, "")*3)&"g" -> 0g
A36: Protein | B36: 2g | C36: =SUM(IF(ISNUMBER( SEARCH("g",B36)), LEFT(B36, LEN(B36)-1)*1, "")*2)&"g" -> 4g | D36: =SUM(IF(ISNUMBER( SEARCH("g",B36)), LEFT(B36, LEN(B36)-1)*1, "")*3)&"g" -> 6g

Sheet Breakfast
A1: Cold Cereal
A2: General Mills Honey Nut Cheerios | H2: With Whole Milk
A3: Serving Size | B3: 1/2 cup | C3: 3/4 cup | D3: 1 cup | E3: 2 Cups(1 Serving) | F3: 4 Cups (2 servings) | H3: 2 Cup Cheerios + 1 Cup Whole Milk | I3: 4 Cup Cereal + 2 Cup Whole Milk
A4: Calories | B4: =(E4/4) -> 73.5 | C4: =(E4*0.375) -> 110.25 | D4: =(E4*0.5) -> 147 | E4: 294 | F4: =(E4*2) -> 588 | H4: =E4+Dairy!D75 -> 454 | I4: =(F4+Dairy!F75) -> 908
A5: Fat | B5: =SUM(IF(ISNUMBER( SEARCH("g",E5)), LEFT(E5, LEN(E5)-1)*1, "")*0.25)&"g" -> 1g | C5: =SUM(IF(ISNUMBER( SEARCH("g",E5)), LEFT(E5, LEN(E5)-1)*1, "")*0.375)&"g" -> 1.5g | D5: =SUM(IF(ISNUMBER( SEARCH("g",E5)), LEFT(E5, LEN(E5)-1)*1, "")*0.5)&"g" -> 2g | E5: 4g | F5: =SUM(IF(ISNUMBER( SEARCH("g",E5)), LEFT(E5, LEN(E5)-1)*1, "")*2)&"g" -> 8g | H5: =SUM(IF(ISNUMBER( SEARCH("g",E5)), LEFT(E5, LEN(E5)-1)*1, "")+(SUM(IF(ISNUMBER( SEARCH("g",Dairy!D76)), LEFT(Dairy!D76, LEN(Dairy!D76)-1)*1, ""))))&"g" -> 12g | I5: =SUM(IF(ISNUMBER( SEARCH("g",F5)), LEFT(F5, LEN(F5)-1)*1, "")+(SUM(IF(ISNUMBER( SEARCH("g",Dairy!F76)), LEFT(Dairy!F76, LEN(Dairy!F76)-1)*1, ""))))&"g" -> 24g
A6: Saturated Fat | B6: =SUM(IF(ISNUMBER( SEARCH("g",E6)), LEFT(E6, LEN(E6)-1)*1, "")*0.25)&"g" -> 0g | C6: =SUM(IF(ISNUMBER( SEARCH("g",E6)), LEFT(E6, LEN(E6)-1)*1, "")*0.375)&"g" -> 0g | D6: =SUM(IF(ISNUMBER( SEARCH("g",E6)), LEFT(E6, LEN(E6)-1)*1, "")*0.5)&"g" -> 0g | E6: 0g | F6: =SUM(IF(ISNUMBER( SEARCH("g",E6)), LEFT(E6, LEN(E6)-1)*1, "")*2)&"g" -> 0g | H6: =SUM(IF(ISNUMBER( SEARCH("g",E6)), LEFT(E6, LEN(E6)-1)*1, "")+(SUM(IF(ISNUMBER( SEARCH("g",Dairy!D77)), LEFT(Dairy!D77, LEN(Dairy!D77)-1)*1, ""))))&"g" -> 5g | I6: =SUM(IF(ISNUMBER( SEARCH("g",F6)), LEFT(F6, LEN(F6)-1)*1, "")+(SUM(IF(ISNUMBER( SEARCH("g",Dairy!F77)), LEFT(Dairy!F77, LEN(Dairy!F77)-1)*1, ""))))&"g" -> 10g
A7: Cholesterol | B7: =SUM(IF(ISNUMBER( SEARCH("mg",E7)), LEFT(E7, LEN(E7)-2)*1, "")*0.25)&"mg" -> 0mg | C7: =SUM(IF(ISNUMBER( SEARCH("mg",E7)), LEFT(E7, LEN(E7)-2)*1, "")*0.375)&"mg" -> 0mg | D7: =SUM(IF(ISNUMBER( SEARCH("mg",E7)), LEFT(E7, LEN(E7)-2)*1, "")*0.5)&"mg" -> 0mg | E7: 0mg | F7: =SUM(IF(ISNUMBER( SEARCH("mg",E7)), LEFT(E7, LEN(E7)-2)*1, "")*2)&"mg" -> 0mg | H7: =SUM(IF(ISNUMBER( SEARCH("mg",E7)), LEFT(E7, LEN(E7)-2)*1, "")+(SUM(IF(ISNUMBER( SEARCH("mg",Dairy!D78)), LEFT(Dairy!D78, LEN(Dairy!D78)-2)*1, ""))))&"mg" -> 35mg | I7: =SUM(IF(ISNUMBER( SEARCH("mg",F7)), LEFT(F7, LEN(F7)-2)*1, "")+(SUM(IF(ISNUMBER( SEARCH("mg",Dairy!F78)), LEFT(Dairy!F78, LEN(Dairy!F78)-2)*1, ""))))&"mg" -> 70mg
A8: Sodium | B8: =SUM(IF(ISNUMBER( SEARCH("mg",E8)), LEFT(E8, LEN(E8)-2)*1, "")*0.25)&"mg" -> 120mg | C8: =SUM(IF(ISNUMBER( SEARCH("mg",E8)), LEFT(E8, LEN(E8)-2)*1, "")*0.375)&"mg" -> 180mg | D8: =SUM(IF(ISNUMBER( SEARCH("mg",E8)), LEFT(E8, LEN(E8)-2)*1, "")*0.5)&"mg" -> 240mg | E8: 480mg | F8: =SUM(IF(ISNUMBER( SEARCH("mg",E8)), LEFT(E8, LEN(E8)-2)*1, "")*2)&"mg" -> 960mg | H8: =SUM(IF(ISNUMBER( SEARCH("mg",E8)), LEFT(E8, LEN(E8)-2)*1, "")+(SUM(IF(ISNUMBER( SEARCH("mg",Dairy!D79)), LEFT(Dairy!D79, LEN(Dairy!D79)-2)*1, ""))))&"mg" -> 610mg | I8: =SUM(IF(ISNUMBER( SEARCH("mg",F8)), LEFT(F8, LEN(F8)-2)*1, "")+(SUM(IF(ISNUMBER( SEARCH("mg",Dairy!F79)), LEFT(Dairy!F79, LEN(Dairy!F79)-2)*1, ""))))&"mg" -> 1220mg
A9: Carbohydrates | B9: =SUM(IF(ISNUMBER( SEARCH("g",E9)), LEFT(E9, LEN(E9)-1)*1, "")*0.25)&"g" -> 15g | C9: =SUM(IF(ISNUMBER( SEARCH("g",E9)), LEFT(E9, LEN(E9)-1)*1, "")*0.375)&"g" -> 22.5g | D9: =SUM(IF(ISNUMBER( SEARCH("g",E9)), LEFT(E9, LEN(E9)-1)*1, "")*0.5)&"g" -> 30g | E9: 60g | F9: =SUM(IF(ISNUMBER( SEARCH("g",E9)), LEFT(E9, LEN(E9)-1)*1, "")*2)&"g" -> 120g | H9: =SUM(IF(ISNUMBER( SEARCH("g",E9)), LEFT(E9, LEN(E9)-1)*1, "")+(SUM(IF(ISNUMBER( SEARCH("g",Dairy!D80)), LEFT(Dairy!D80, LEN(Dairy!D80)-1)*1, ""))))&"g" -> 73g | I9: =SUM(IF(ISNUMBER( SEARCH("g",F9)), LEFT(F9, LEN(F9)-1)*1, "")+(SUM(IF(ISNUMBER( SEARCH("g",Dairy!F80)), LEFT(Dairy!F80, LEN(Dairy!F80)-1)*1, ""))))&"g" -> 146g
A10: Fiber | B10: =SUM(IF(ISNUMBER( SEARCH("g",E10)), LEFT(E10, LEN(E10)-1)*1, "")*0.25)&"g" -> 2g | C10: =SUM(IF(ISNUMBER( SEARCH("g",E10)), LEFT(E10, LEN(E10)-1)*1, "")*0.375)&"g" -> 3g | D10: =SUM(IF(ISNUMBER( SEARCH("g",E10)), LEFT(E10, LEN(E10)-1)*1, "")*0.5)&"g" -> 4g | E10: 8g | F10: =SUM(IF(ISNUMBER( SEARCH("g",E10)), LEFT(E10, LEN(E10)-1)*1, "")*2)&"g" -> 16g | H10: =SUM(IF(ISNUMBER( SEARCH("g",E10)), LEFT(E10, LEN(E10)-1)*1, "")+(SUM(IF(ISNUMBER( SEARCH("g",Dairy!D81)), LEFT(Dairy!D81, LEN(Dairy!D81)-1)*1, ""))))&"g" -> 8g | I10: =SUM(IF(ISNUMBER( SEARCH("g",F10)), LEFT(F10, LEN(F10)-1)*1, "")+(SUM(IF(ISNUMBER( SEARCH("g",Dairy!F81)), LEFT(Dairy!F81, LEN(Dairy!F81)-1)*1, ""))))&"g" -> 16g
A11: Sugar | B11: =SUM(IF(ISNUMBER( SEARCH("g",E11)), LEFT(E11, LEN(E11)-1)*1, "")*0.25)&"g" -> 6g | C11: =SUM(IF(ISNUMBER( SEARCH("g",E11)), LEFT(E11, LEN(E11)-1)*1, "")*0.375)&"g" -> 9g | D11: =SUM(IF(ISNUMBER( SEARCH("g",E11)), LEFT(E11, LEN(E11)-1)*1, "")*0.5)&"g" -> 12g | E11: 24g | F11: =SUM(IF(ISNUMBER( SEARCH("g",E11)), LEFT(E11, LEN(E11)-1)*1, "")*2)&"g" -> 48g | H11: =SUM(IF(ISNUMBER( SEARCH("g",E11)), LEFT(E11, LEN(E11)-1)*1, "")+(SUM(IF(ISNUMBER( SEARCH("g",Dairy!D82)), LEFT(Dairy!D82, LEN(Dairy!D82)-1)*1, ""))))&"g" -> 36g | I11: =SUM(IF(ISNUMBER( SEARCH("g",F11)), LEFT(F11, LEN(F11)-1)*1, "")+(SUM(IF(ISNUMBER( SEARCH("g",Dairy!F82)), LEFT(Dairy!F82, LEN(Dairy!F82)-1)*1, ""))))&"g" -> 72g
A12: Added Sugar | B12: =SUM(IF(ISNUMBER( SEARCH("g",E12)), LEFT(E12, LEN(E12)-1)*1, "")*0.25)&"g" -> 0g | C12: =SUM(IF(ISNUMBER( SEARCH("g",E12)), LEFT(E12, LEN(E12)-1)*1, "")*0.375)&"g" -> 0g | D12: =SUM(IF(ISNUMBER( SEARCH("g",E12)), LEFT(E12, LEN(E12)-1)*1, "")*0.5)&"g" -> 0g | E12: 0g | F12: =SUM(IF(ISNUMBER( SEARCH("g",E12)), LEFT(E12, LEN(E12)-1)*1, "")*2)&"g" -> 0g | H12: =SUM(IF(ISNUMBER( SEARCH("g",E12)), LEFT(E12, LEN(E12)-1)*1, "")+(SUM(IF(ISNUMBER( SEARCH("g",Dairy!D83)), LEFT(Dairy!D83, LEN(Dairy!D83)-1)*1, ""))))&"g" -> 0g | I12: =SUM(IF(ISNUMBER( SEARCH("g",F12)), LEFT(F12, LEN(F12)-1)*1, "")+(SUM(IF(ISNUMBER( SEARCH("g",Dairy!F83)), LEFT(Dairy!F83, LEN(Dairy!F83)-1)*1, ""))))&"g" -> 0g
A13: Protein | B13: =SUM(IF(ISNUMBER( SEARCH("g",E13)), LEFT(E13, LEN(E13)-1)*1, "")*0.25)&"g" -> 2g | C13: =SUM(IF(ISNUMBER( SEARCH("g",E13)), LEFT(E13, LEN(E13)-1)*1, "")*0.375)&"g" -> 3g | D13: =SUM(IF(ISNUMBER( SEARCH("g",E13)), LEFT(E13, LEN(E13)-1)*1, "")*0.5)&"g" -> 4g | E13: 8g | F13: =SUM(IF(ISNUMBER( SEARCH("g",E13)), LEFT(E13, LEN(E13)-1)*1, "")*2)&"g" -> 16g | H13: =SUM(IF(ISNUMBER( SEARCH("g",E13)), LEFT(E13, LEN(E13)-1)*1, "")+(SUM(IF(ISNUMBER( SEARCH("g",Dairy!D84)), LEFT(Dairy!D84, LEN(Dairy!D84)-1)*1, ""))))&"g" -> 17g | I13: =SUM(IF(ISNUMBER( SEARCH("g",F13)), LEFT(F13, LEN(F13)-1)*1, "")+(SUM(IF(ISNUMBER( SEARCH("g",Dairy!F84)), LEFT(Dairy!F84, LEN(Dairy!F84)-1)*1, ""))))&"g" -> 34g
A14: General Mills Honey Nut Cheerios Apple Cinnamon
A15: Serving Size | B15: 1/2 Cup | C15: 3/4 Cup | D15: 1 cup | E15: 2 Cups(1 Serving) | F15: 4 Cups (2 servings) | H15: 2 Cup Cheerios + 1 Cup Whole Milk | I15: 4 Cup Cereal + 2 Cup Whole Milk
A16: Calories | B16: =(E16/4) -> 55.5 | C16: =(E16*0.375) -> 83.25 | D16: =(E16*0.5) -> 111 | E16: 222 | F16: =(E16*2) -> 444 | H16: =E16+Dairy!D75 -> 382 | I16: =(F16+Dairy!F75) -> 764
A17: Fat | B17: =SUM(IF(ISNUMBER( SEARCH("g",E17)), LEFT(E17, LEN(E17)-1)*1, "")*0.25)&"g" -> 1.5g | C17: =SUM(IF(ISNUMBER( SEARCH("g",E17)), LEFT(E17, LEN(E17)-1)*1, "")*0.375)&"g" -> 2.25g | D17: =SUM(IF(ISNUMBER( SEARCH("g",E17)), LEFT(E17, LEN(E17)-1)*1, "")*0.5)&"g" -> 3g | E17: 6g | F17: =SUM(IF(ISNUMBER( SEARCH("g",E17)), LEFT(E17, LEN(E17)-1)*1, "")*2)&"g" -> 12g | H17: =SUM(IF(ISNUMBER( SEARCH("g",E17)), LEFT(E17, LEN(E17)-1)*1, "")+(SUM(IF(ISNUMBER( SEARCH("g",Dairy!D76)), LEFT(Dairy!D76, LEN(Dairy!D76)-1)*1, ""))))&"g" -> 14g | I17: =SUM(IF(ISNUMBER( SEARCH("g",F17)), LEFT(F17, LEN(F17)-1)*1, "")+(SUM(IF(ISNUMBER( SEARCH("g",Dairy!F76)), LEFT(Dairy!F76, LEN(Dairy!F76)-1)*1, ""))))&"g" -> 28g
A18: Saturated Fat | B18: =SUM(IF(ISNUMBER( SEARCH("g",E18)), LEFT(E18, LEN(E18)-1)*1, "")*0.25)&"g" -> 0g | C18: =SUM(IF(ISNUMBER( SEARCH("g",E18)), LEFT(E18, LEN(E18)-1)*1, "")*0.375)&"g" -> 0g | D18: =SUM(IF(ISNUMBER( SEARCH("g",E18)), LEFT(E18, LEN(E18)-1)*1, "")*0.5)&"g" -> 0g | E18: 0g | F18: =SUM(IF(ISNUMBER( SEARCH("g",E18)), LEFT(E18, LEN(E18)-1)*1, "")*2)&"g" -> 0g | H18: =SUM(IF(ISNUMBER( SEARCH("g",E18)), LEFT(E18, LEN(E18)-1)*1, "")+(SUM(IF(ISNUMBER( SEARCH("g",Dairy!D77)), LEFT(Dairy!D77, LEN(Dairy!D77)-1)*1, ""))))&"g" -> 5g | I18: =SUM(IF(ISNUMBER( SEARCH("g",F18)), LEFT(F18, LEN(F18)-1)*1, "")+(SUM(IF(ISNUMBER( SEARCH("g",Dairy!F77)), LEFT(Dairy!F77, LEN(Dairy!F77)-1)*1, ""))))&"g" -> 10g
A19: Cholesterol | B19: =SUM(IF(ISNUMBER( SEARCH("mg",E19)), LEFT(E19, LEN(E19)-2)*1, "")*0.25)&"mg" -> 0mg | C19: =SUM(IF(ISNUMBER( SEARCH("mg",E19)), LEFT(E19, LEN(E19)-2)*1, "")*0.375)&"mg" -> 0mg | D19: =SUM(IF(ISNUMBER( SEARCH("mg",E19)), LEFT(E19, LEN(E19)-2)*1, "")*0.5)&"mg" -> 0mg | E19: 0mg | F19: =SUM(IF(ISNUMBER( SEARCH("mg",E19)), LEFT(E19, LEN(E19)-2)*1, "")*2)&"mg" -> 0mg | H19: =SUM(IF(ISNUMBER( SEARCH("mg",E19)), LEFT(E19, LEN(E19)-2)*1, "")+(SUM(IF(ISNUMBER( SEARCH("mg",Dairy!D78)), LEFT(Dairy!D78, LEN(Dairy!D78)-2)*1, ""))))&"mg" -> 35mg | I19: =SUM(IF(ISNUMBER( SEARCH("mg",F19)), LEFT(F19, LEN(F19)-2)*1, "")+(SUM(IF(ISNUMBER( SEARCH("mg",Dairy!F78)), LEFT(Dairy!F78, LEN(Dairy!F78)-2)*1, ""))))&"mg" -> 70mg
A20: Sodium | B20: =SUM(IF(ISNUMBER( SEARCH("mg",E20)), LEFT(E20, LEN(E20)-2)*1, "")*0.25)&"mg" -> 74mg | C20: =SUM(IF(ISNUMBER( SEARCH("mg",E20)), LEFT(E20, LEN(E20)-2)*1, "")*0.375)&"mg" -> 111mg | D20: =SUM(IF(ISNUMBER( SEARCH("mg",E20)), LEFT(E20, LEN(E20)-2)*1, "")*0.5)&"mg" -> 148mg | E20: 296mg | F20: =SUM(IF(ISNUMBER( SEARCH("mg",E20)), LEFT(E20, LEN(E20)-2)*1, "")*2)&"mg" -> 592mg | H20: =SUM(IF(ISNUMBER( SEARCH("mg",E20)), LEFT(E20, LEN(E20)-2)*1, "")+(SUM(IF(ISNUMBER( SEARCH("mg",Dairy!D79)), LEFT(Dairy!D79, LEN(Dairy!D79)-2)*1, ""))))&"mg" -> 426mg | I20: =SUM(IF(ISNUMBER( SEARCH("mg",F20)), LEFT(F20, LEN(F20)-2)*1, "")+(SUM(IF(ISNUMBER( SEARCH("mg",Dairy!F79)), LEFT(Dairy!F79, LEN(Dairy!F79)-2)*1, ""))))&"mg" -> 852mg
A21: Carbohydrates | B21: =SUM(IF(ISNUMBER( SEARCH("g",E21)), LEFT(E21, LEN(E21)-1)*1, "")*0.25)&"g" -> 22.5g | C21: =SUM(IF(ISNUMBER( SEARCH("g",E21)), LEFT(E21, LEN(E21)-1)*1, "")*0.375)&"g" -> 33.75g | D21: =SUM(IF(ISNUMBER( SEARCH("g",E21)), LEFT(E21, LEN(E21)-1)*1, "")*0.5)&"g" -> 45g | E21: 90g | F21: =SUM(IF(ISNUMBER( SEARCH("g",E21)), LEFT(E21, LEN(E21)-1)*1, "")*2)&"g" -> 180g | H21: =SUM(IF(ISNUMBER( SEARCH("g",E21)), LEFT(E21, LEN(E21)-1)*1, "")+(SUM(IF(ISNUMBER( SEARCH("g",Dairy!D80)), LEFT(Dairy!D80, LEN(Dairy!D80)-1)*1, ""))))&"g" -> 103g | I21: =SUM(IF(ISNUMBER( SEARCH("g",F21)), LEFT(F21, LEN(F21)-1)*1, "")+(SUM(IF(ISNUMBER( SEARCH("g",Dairy!F80)), LEFT(Dairy!F80, LEN(Dairy!F80)-1)*1, ""))))&"g" -> 206g
A22: Fiber | B22: =SUM(IF(ISNUMBER( SEARCH("g",E22)), LEFT(E22, LEN(E22)-1)*1, "")*0.25)&"g" -> 30g | C22: =SUM(IF(ISNUMBER( SEARCH("g",E22)), LEFT(E22, LEN(E22)-1)*1, "")*0.375)&"g" -> 45g | D22: =SUM(IF(ISNUMBER( SEARCH("g",E22)), LEFT(E22, LEN(E22)-1)*1, "")*0.5)&"g" -> 60g | E22: 120g | F22: =SUM(IF(ISNUMBER( SEARCH("g",E22)), LEFT(E22, LEN(E22)-1)*1, "")*2)&"g" -> 240g | H22: =SUM(IF(ISNUMBER( SEARCH("g",E22)), LEFT(E22, LEN(E22)-1)*1, "")+(SUM(IF(ISNUMBER( SEARCH("g",Dairy!D81)), LEFT(Dairy!D81, LEN(Dairy!D81)-1)*1, ""))))&"g" -> 120g | I22: =SUM(IF(ISNUMBER( SEARCH("g",F22)), LEFT(F22, LEN(F22)-1)*1, "")+(SUM(IF(ISNUMBER( SEARCH("g",Dairy!F81)), LEFT(Dairy!F81, LEN(Dairy!F81)-1)*1, ""))))&"g" -> 240g
A23: Sugar | B23: =SUM(IF(ISNUMBER( SEARCH("g",E23)), LEFT(E23, LEN(E23)-1)*1, "")*0.25)&"g" -> 9g | C23: =SUM(IF(ISNUMBER( SEARCH("g",E23)), LEFT(E23, LEN(E23)-1)*1, "")*0.375)&"g" -> 13.5g | D23: =SUM(IF(ISNUMBER( SEARCH("g",E23)), LEFT(E23, LEN(E23)-1)*1, "")*0.5)&"g" -> 18g | E23: 36g | F23: =SUM(IF(ISNUMBER( SEARCH("g",E23)), LEFT(E23, LEN(E23)-1)*1, "")*2)&"g" -> 72g | H23: =SUM(IF(ISNUMBER( SEARCH("g",E23)), LEFT(E23, LEN(E23)-1)*1, "")+(SUM(IF(ISNUMBER( SEARCH("g",Dairy!D82)), LEFT(Dairy!D82, LEN(Dairy!D82)-1)*1, ""))))&"g" -> 48g | I23: =SUM(IF(ISNUMBER( SEARCH("g",F23)), LEFT(F23, LEN(F23)-1)*1, "")+(SUM(IF(ISNUMBER( SEARCH("g",Dairy!F82)), LEFT(Dairy!F82, LEN(Dairy!F82)-1)*1, ""))))&"g" -> 96g
A24: Added Sugar | B24: =SUM(IF(ISNUMBER( SEARCH("g",E24)), LEFT(E24, LEN(E24)-1)*1, "")*0.25)&"g" -> 0g | C24: =SUM(IF(ISNUMBER( SEARCH("g",E24)), LEFT(E24, LEN(E24)-1)*1, "")*0.375)&"g" -> 0g | D24: =SUM(IF(ISNUMBER( SEARCH("g",E24)), LEFT(E24, LEN(E24)-1)*1, "")*0.5)&"g" -> 0g | E24: 0g | F24: =SUM(IF(ISNUMBER( SEARCH("g",E24)), LEFT(E24, LEN(E24)-1)*1, "")*2)&"g" -> 0g | H24: =SUM(IF(ISNUMBER( SEARCH("g",E24)), LEFT(E24, LEN(E24)-1)*1, "")+(SUM(IF(ISNUMBER( SEARCH("g",Dairy!D83)), LEFT(Dairy!D83, LEN(Dairy!D83)-1)*1, ""))))&"g" -> 0g | I24: =SUM(IF(ISNUMBER( SEARCH("g",F24)), LEFT(F24, LEN(F24)-1)*1, "")+(SUM(IF(ISNUMBER( SEARCH("g",Dairy!F83)), LEFT(Dairy!F83, LEN(Dairy!F83)-1)*1, ""))))&"g" -> 0g
A25: Protein | B25: =SUM(IF(ISNUMBER( SEARCH("g",E25)), LEFT(E25, LEN(E25)-1)*1, "")*0.25)&"g" -> 3g | C25: =SUM(IF(ISNUMBER( SEARCH("g",E25)), LEFT(E25, LEN(E25)-1)*1, "")*0.375)&"g" -> 4.5g | D25: =SUM(IF(ISNUMBER( SEARCH("g",E25)), LEFT(E25, LEN(E25)-1)*1, "")*0.5)&"g" -> 6g | E25: 12g | F25: =SUM(IF(ISNUMBER( SEARCH("g",E25)), LEFT(E25, LEN(E25)-1)*1, "")*2)&"g" -> 24g | H25: =SUM(IF(ISNUMBER( SEARCH("g",E25)), LEFT(E25, LEN(E25)-1)*1, "")+(SUM(IF(ISNUMBER( SEARCH("g",Dairy!D84)), LEFT(Dairy!D84, LEN(Dairy!D84)-1)*1, ""))))&"g" -> 21g | I25: =SUM(IF(ISNUMBER( SEARCH("g",F25)), LEFT(F25, LEN(F25)-1)*1, "")+(SUM(IF(ISNUMBER( SEARCH("g",Dairy!F84)), LEFT(Dairy!F84, LEN(Dairy!F84)-1)*1, ""))))&"g" -> 42g
A26: Post Honey Bunches of Oats, Strawberry
A27: Serving Size | B27: 1/2 Cup | C27: 3/4 Cup | D27: 1 cup | E27: 2 Cups(1 Serving) | F27: 4 Cups (2 servings) | H27: 2 Cups Cereal + 1 Cup Whole Milk | I27: 4 Cups Cereal + 2 Cups Whole Milk
A28: Calories | B28: =(E28/4) -> 80 | C28: =(E28*0.375) -> 120 | D28: =(E28*0.5) -> 160 | E28: 320 | F28: =(E28*2) -> 640 | H28: =E28+Dairy!D75 -> 480 | I28: =(F28+Dairy!F75) -> 960
A29: Fat | B29: =SUM(IF(ISNUMBER( SEARCH("g",E29)), LEFT(E29, LEN(E29)-1)*1, "")*0.25)&"g" -> 1g | C29: =SUM(IF(ISNUMBER( SEARCH("g",E29)), LEFT(E29, LEN(E29)-1)*1, "")*0.375)&"g" -> 1.5g | D29: =SUM(IF(ISNUMBER( SEARCH("g",E29)), LEFT(E29, LEN(E29)-1)*1, "")*0.5)&"g" -> 2g | E29: 4g | F29: =SUM(IF(ISNUMBER( SEARCH("g",E29)), LEFT(E29, LEN(E29)-1)*1, "")*2)&"g" -> 8g | H29: =SUM(IF(ISNUMBER( SEARCH("g",E29)), LEFT(E29, LEN(E29)-1)*1, "")+(SUM(IF(ISNUMBER( SEARCH("g",Dairy!D76)), LEFT(Dairy!D76, LEN(Dairy!D76)-1)*1, ""))))&"g" -> 12g | I29: =SUM(IF(ISNUMBER( SEARCH("g",F29)), LEFT(F29, LEN(F29)-1)*1, "")+(SUM(IF(ISNUMBER( SEARCH("g",Dairy!F76)), LEFT(Dairy!F76, LEN(Dairy!F76)-1)*1, ""))))&"g" -> 24g
A30: Saturated Fat | B30: =SUM(IF(ISNUMBER( SEARCH("g",E30)), LEFT(E30, LEN(E30)-1)*1, "")*0.25)&"g" -> 0g | C30: =SUM(IF(ISNUMBER( SEARCH("g",E30)), LEFT(E30, LEN(E30)-1)*1, "")*0.375)&"g" -> 0g | D30: =SUM(IF(ISNUMBER( SEARCH("g",E30)), LEFT(E30, LEN(E30)-1)*1, "")*0.5)&"g" -> 0g | E30: 0g | F30: =SUM(IF(ISNUMBER( SEARCH("g",E30)), LEFT(E30, LEN(E30)-1)*1, "")*2)&"g" -> 0g | H30: =SUM(IF(ISNUMBER( SEARCH("g",E30)), LEFT(E30, LEN(E30)-1)*1, "")+(SUM(IF(ISNUMBER( SEARCH("g",Dairy!D77)), LEFT(Dairy!D77, LEN(Dairy!D77)-1)*1, ""))))&"g" -> 5g | I30: =SUM(IF(ISNUMBER( SEARCH("g",F30)), LEFT(F30, LEN(F30)-1)*1, "")+(SUM(IF(ISNUMBER( SEARCH("g",Dairy!F77)), LEFT(Dairy!F77, LEN(Dairy!F77)-1)*1, ""))))&"g" -> 10g
A31: Cholesterol | B31: =SUM(IF(ISNUMBER( SEARCH("mg",E31)), LEFT(E31, LEN(E31)-2)*1, "")*0.25)&"mg" -> 0mg | C31: =SUM(IF(ISNUMBER( SEARCH("mg",E31)), LEFT(E31, LEN(E31)-2)*1, "")*0.375)&"mg" -> 0mg | D31: =SUM(IF(ISNUMBER( SEARCH("mg",E31)), LEFT(E31, LEN(E31)-2)*1, "")*0.5)&"mg" -> 0mg | E31: 0mg | F31: =SUM(IF(ISNUMBER( SEARCH("mg",E31)), LEFT(E31, LEN(E31)-2)*1, "")*2)&"mg" -> 0mg | H31: =SUM(IF(ISNUMBER( SEARCH("mg",E31)), LEFT(E31, LEN(E31)-2)*1, "")+(SUM(IF(ISNUMBER( SEARCH("mg",Dairy!D78)), LEFT(Dairy!D78, LEN(Dairy!D78)-2)*1, ""))))&"mg" -> 35mg | I31: =SUM(IF(ISNUMBER( SEARCH("mg",F31)), LEFT(F31, LEN(F31)-2)*1, "")+(SUM(IF(ISNUMBER( SEARCH("mg",Dairy!F78)), LEFT(Dairy!F78, LEN(Dairy!F78)-2)*1, ""))))&"mg" -> 70mg
A32: Sodium | B32: =SUM(IF(ISNUMBER( SEARCH("mg",E32)), LEFT(E32, LEN(E32)-2)*1, "")*0.25)&"mg" -> 85mg | C32: =SUM(IF(ISNUMBER( SEARCH("mg",E32)), LEFT(E32, LEN(E32)-2)*1, "")*0.375)&"mg" -> 127.5mg | D32: =SUM(IF(ISNUMBER( SEARCH("mg",E32)), LEFT(E32, LEN(E32)-2)*1, "")*0.5)&"mg" -> 170mg | E32: 340mg | F32: =SUM(IF(ISNUMBER( SEARCH("mg",E32)), LEFT(E32, LEN(E32)-2)*1, "")*2)&"mg" -> 680mg | H32: =SUM(IF(ISNUMBER( SEARCH("mg",E32)), LEFT(E32, LEN(E32)-2)*1, "")+(SUM(IF(ISNUMBER( SEARCH("mg",Dairy!D79)), LEFT(Dairy!D79, LEN(Dairy!D79)-2)*1, ""))))&"mg" -> 470mg | I32: =SUM(IF(ISNUMBER( SEARCH("mg",F32)), LEFT(F32, LEN(F32)-2)*1, "")+(SUM(IF(ISNUMBER( SEARCH("mg",Dairy!F79)), LEFT(Dairy!F79, LEN(Dairy!F79)-2)*1, ""))))&"mg" -> 940mg
A33: Carbohydrates | B33: =SUM(IF(ISNUMBER( SEARCH("g",E33)), LEFT(E33, LEN(E33)-1)*1, "")*0.25)&"g" -> 17g | C33: =SUM(IF(ISNUMBER( SEARCH("g",E33)), LEFT(E33, LEN(E33)-1)*1, "")*0.375)&"g" -> 25.5g | D33: =SUM(IF(ISNUMBER( SEARCH("g",E33)), LEFT(E33, LEN(E33)-1)*1, "")*0.5)&"g" -> 34g | E33: 68g | F33: =SUM(IF(ISNUMBER( SEARCH("g",E33)), LEFT(E33, LEN(E33)-1)*1, "")*2)&"g" -> 136g | H33: =SUM(IF(ISNUMBER( SEARCH("g",E33)), LEFT(E33, LEN(E33)-1)*1, "")+(SUM(IF(ISNUMBER( SEARCH("g",Dairy!D80)), LEFT(Dairy!D80, LEN(Dairy!D80)-1)*1, ""))))&"g" -> 81g | I33: =SUM(IF(ISNUMBER( SEARCH("g",F33)), LEFT(F33, LEN(F33)-1)*1, "")+(SUM(IF(ISNUMBER( SEARCH("g",Dairy!F80)), LEFT(Dairy!F80, LEN(Dairy!F80)-1)*1, ""))))&"g" -> 162g
A34: Fiber | B34: =SUM(IF(ISNUMBER( SEARCH("g",E34)), LEFT(E34, LEN(E34)-1)*1, "")*0.25)&"g" -> 1g | C34: =SUM(IF(ISNUMBER( SEARCH("g",E34)), LEFT(E34, LEN(E34)-1)*1, "")*0.375)&"g" -> 1.5g | D34: =SUM(IF(ISNUMBER( SEARCH("g",E34)), LEFT(E34, LEN(E34)-1)*1, "")*0.5)&"g" -> 2g | E34: 4g | F34: =SUM(IF(ISNUMBER( SEARCH("g",E34)), LEFT(E34, LEN(E34)-1)*1, "")*2)&"g" -> 8g | H34: =SUM(IF(ISNUMBER( SEARCH("g",E34)), LEFT(E34, LEN(E34)-1)*1, "")+(SUM(IF(ISNUMBER( SEARCH("g",Dairy!D81)), LEFT(Dairy!D81, LEN(Dairy!D81)-1)*1, ""))))&"g" -> 4g | I34: =SUM(IF(ISNUMBER( SEARCH("g",F34)), LEFT(F34, LEN(F34)-1)*1, "")+(SUM(IF(ISNUMBER( SEARCH("g",Dairy!F81)), LEFT(Dairy!F81, LEN(Dairy!F81)-1)*1, ""))))&"g" -> 8g
A35: Sugar | B35: =SUM(IF(ISNUMBER( SEARCH("g",E35)), LEFT(E35, LEN(E35)-1)*1, "")*0.25)&"g" -> 5.5g | C35: =SUM(IF(ISNUMBER( SEARCH("g",E35)), LEFT(E35, LEN(E35)-1)*1, "")*0.375)&"g" -> 8.25g | D35: =SUM(IF(ISNUMBER( SEARCH("g",E35)), LEFT(E35, LEN(E35)-1)*1, "")*0.5)&"g" -> 11g | E35: 22g | F35: =SUM(IF(ISNUMBER( SEARCH("g",E35)), LEFT(E35, LEN(E35)-1)*1, "")*2)&"g" -> 44g | H35: =SUM(IF(ISNUMBER( SEARCH("g",E35)), LEFT(E35, LEN(E35)-1)*1, "")+(SUM(IF(ISNUMBER( SEARCH("g",Dairy!D82)), LEFT(Dairy!D82, LEN(Dairy!D82)-1)*1, ""))))&"g" -> 34g | I35: =SUM(IF(ISNUMBER( SEARCH("g",F35)), LEFT(F35, LEN(F35)-1)*1, "")+(SUM(IF(ISNUMBER( SEARCH("g",Dairy!F82)), LEFT(Dairy!F82, LEN(Dairy!F82)-1)*1, ""))))&"g" -> 68g
A36: Added Sugar | B36: =SUM(IF(ISNUMBER( SEARCH("g",E36)), LEFT(E36, LEN(E36)-1)*1, "")*0.25)&"g" -> 4.5g | C36: =SUM(IF(ISNUMBER( SEARCH("g",E36)), LEFT(E36, LEN(E36)-1)*1, "")*0.375)&"g" -> 6.75g | D36: =SUM(IF(ISNUMBER( SEARCH("g",E36)), LEFT(E36, LEN(E36)-1)*1, "")*0.5)&"g" -> 9g | E36: 18g | F36: =SUM(IF(ISNUMBER( SEARCH("g",E36)), LEFT(E36, LEN(E36)-1)*1, "")*2)&"g" -> 36g | H36: =SUM(IF(ISNUMBER( SEARCH("g",E36)), LEFT(E36, LEN(E36)-1)*1, "")+(SUM(IF(ISNUMBER( SEARCH("g",Dairy!D83)), LEFT(Dairy!D83, LEN(Dairy!D83)-1)*1, ""))))&"g" -> 18g | I36: =SUM(IF(ISNUMBER( SEARCH("g",F36)), LEFT(F36, LEN(F36)-1)*1, "")+(SUM(IF(ISNUMBER( SEARCH("g",Dairy!F83)), LEFT(Dairy!F83, LEN(Dairy!F83)-1)*1, ""))))&"g" -> 36g
A37: Protein | B37: =SUM(IF(ISNUMBER( SEARCH("g",E37)), LEFT(E37, LEN(E37)-1)*1, "")*0.25)&"g" -> 1.5g | C37: =SUM(IF(ISNUMBER( SEARCH("g",E37)), LEFT(E37, LEN(E37)-1)*1, "")*0.375)&"g" -> 2.25g | D37: =SUM(IF(ISNUMBER( SEARCH("g",E37)), LEFT(E37, LEN(E37)-1)*1, "")*0.5)&"g" -> 3g | E37: 6g | F37: =SUM(IF(ISNUMBER( SEARCH("g",E37)), LEFT(E37, LEN(E37)-1)*1, "")*2)&"g" -> 12g | H37: =SUM(IF(ISNUMBER( SEARCH("g",E37)), LEFT(E37, LEN(E37)-1)*1, "")+(SUM(IF(ISNUMBER( SEARCH("g",Dairy!D84)), LEFT(Dairy!D84, LEN(Dairy!D84)-1)*1, ""))))&"g" -> 15g | I37: =SUM(IF(ISNUMBER( SEARCH("g",F37)), LEFT(F37, LEN(F37)-1)*1, "")+(SUM(IF(ISNUMBER( SEARCH("g",Dairy!F84)), LEFT(Dairy!F84, LEN(Dairy!F84)-1)*1, ""))))&"g" -> 30g
A38: Quaker Cap'n Crunch Peanut Butter Crunch
A39: Serving Size | B39: 1/2 Cup | C39: 3/4 Cup | D39: 1 cup | E39: 2 Cups(1 Serving) | F39: 4 Cups (2 servings) | H39: 2 Cups Cereal + 1 Cup Whole Milk | I39: 4 Cups Cereal + 2 Cups Whole Milk
A40: Calories | B40: =(E40/4) -> 85 | C40: =(E40*0.375) -> 127.5 | D40: =(E40*0.5) -> 170 | E40: 340 | F40: =(E40*2) -> 680 | H40: =E40+Dairy!D75 -> 500 | I40: =(F40+Dairy!F75) -> 1000
...

Sheet Drinks
A1: Lipton Green Tea Citrus
A2: Serving Size | B2: 1 bottle (16.9 oz)
A3: Calories | B3: 100
A4: Fat | B4: 0g
A5: Saturated Fat | B5: 0g
A6: Cholesterol | B6: 0mg
A7: Sodium | B7: 150mg
A8: Carbohydrates | B8: 25g
A9: Fiber | B9: 0g
A10: Sugar | B10: 25g
A11: Added Sugar | B11: 25g
A12: Protein | B12: 0g
A13: Redbull Energy Drink
A14: Serving Size | B14: 1 can (8.4 oz)
A15: Calories | B15: 110
A16: Fat | B16: 0g
A17: Saturated Fat | B17: 0g
A18: Cholesterol | B18: 0mg
A19: Sodium | B19: 105mg
A20: Carbohydrates | B20: 29g
A21: Fiber | B21: 0g
A22: Sugar | B22: 27g
A23: Added Sugar | B23: 27g
A24: Protein | B24: 0g
A25: Dutch Bros Annihilator
A26: Serving Size | B26: 20 ounces
A27: Calories | B27: 546
A28: Fat | B28: 37g
A29: Saturated Fat | B29: 21g
A30: Cholesterol | B30: 161mg
A31: Sodium | B31: 0mg
A32: Carbohydrates | B32: 47g
A33: Fiber | B33: 0g
A34: Sugar | B34: 35g
A35: Added Sugar | B35: 0g
A36: Protein | B36: 10g
A37: Dutch Bros Cocomo Freeze
A38: Serving Size | B38: 16 ounces
A39: Calories | B39: 429
A40: Fat | B40: 9g
...

Sheet Dairy
A1: Eggs
A2: Serving Size | B2: 1 Egg | C2: 2 Eggs | D2: 3 Eggs | E2: 4 Eggs
A3: Calories | B3: 70 | C3: =(B3*2) -> 140 | D3: =(B3*3) -> 210 | E3: =(B3*4) -> 280
A4: Fat | B4: 5g | C4: =SUM(IF(ISNUMBER( SEARCH("g",B4)), LEFT(B4, LEN(B4)-1)*1, "")+(SUM(IF(ISNUMBER( SEARCH("g",B4)), LEFT(B4, LEN(B4)-1)*1, ""))))&"g" -> 10g | D4: =SUM(IF(ISNUMBER( SEARCH("g",C4)), LEFT(C4, LEN(C4)-1)*1, "")+(SUM(IF(ISNUMBER( SEARCH("g",C4)), LEFT(C4, LEN(C4)-1)*1, "")))/2)&"g" -> 15g | E4: =SUM(IF(ISNUMBER( SEARCH("g",B4)), LEFT(B4, LEN(B4)-1)*1, "")*4)&"g" -> 20g
A5: Saturated Fat | B5: 1.5g | C5: =SUM(IF(ISNUMBER( SEARCH("g",B5)), LEFT(B5, LEN(B5)-1)*1, "")*2)&"mg" -> 3mg | D5: =SUM(IF(ISNUMBER( SEARCH("g",B5)), LEFT(B5, LEN(B5)-1)*1, "")*3)&"g" -> 4.5g | E5: =SUM(IF(ISNUMBER( SEARCH("g",B5)), LEFT(B5, LEN(B5)-1)*1, "")*4)&"g" -> 6g
A6: Cholesterol | B6: 185mg | C6: =SUM(IF(ISNUMBER( SEARCH("mg",B6)), LEFT(B6, LEN(B6)-2)*1, "")*2)&"mg" -> 370mg | D6: =SUM(IF(ISNUMBER( SEARCH("mg",B6)), LEFT(B6, LEN(B6)-2)*1, "")*3)&"mg" -> 555mg | E6: =SUM(IF(ISNUMBER( SEARCH("mg",B6)), LEFT(B6, LEN(B6)-2)*1, "")*4)&"mg" -> 740mg
A7: Sodium | B7: 70mg | C7: =SUM(IF(ISNUMBER( SEARCH("mg",B7)), LEFT(B7, LEN(B7)-2)*1, "")*2)&"mg" -> 140mg | D7: =SUM(IF(ISNUMBER( SEARCH("mg",B7)), LEFT(B7, LEN(B7)-2)*1, "")*3)&"mg" -> 210mg | E7: =SUM(IF(ISNUMBER( SEARCH("mg",B7)), LEFT(B7, LEN(B7)-2)*1, "")*4)&"mg" -> 280mg
A8: Carbs | B8: 0g | C8: =SUM(IF(ISNUMBER( SEARCH("g",B8)), LEFT(B8, LEN(B8)-1)*1, "")*2)&"g" -> 0g | D8: =SUM(IF(ISNUMBER( SEARCH("g",B8)), LEFT(B8, LEN(B8)-1)*1, "")*3)&"g" -> 0g | E8: =SUM(IF(ISNUMBER( SEARCH("g",B8)), LEFT(B8, LEN(B8)-1)*1, "")*4)&"g" -> 0g
A9: Fiber | B9: 0g | C9: =SUM(IF(ISNUMBER( SEARCH("g",B9)), LEFT(B9, LEN(B9)-1)*1, "")*2)&"g" -> 0g | D9: =SUM(IF(ISNUMBER( SEARCH("g",B9)), LEFT(B9, LEN(B9)-1)*1, "")*3)&"g" -> 0g | E9: =SUM(IF(ISNUMBER( SEARCH("g",B9)), LEFT(B9, LEN(B9)-1)*1, "")*4)&"g" -> 0g
A10: Sugar | B10: 0g | C10: =SUM(IF(ISNUMBER( SEARCH("g",B10)), LEFT(B10, LEN(B10)-1)*1, "")*2)&"g" -> 0g | D10: =SUM(IF(ISNUMBER( SEARCH("g",B10)), LEFT(B10, LEN(B10)-1)*1, "")*3)&"g" -> 0g | E10: =SUM(IF(ISNUMBER( SEARCH("g",B10)), LEFT(B10, LEN(B10)-1)*1, "")*4)&"g" -> 0g
A11: Added Sugar | B11: 0g | C11: =SUM(IF(ISNUMBER( SEARCH("g",B11)), LEFT(B11, LEN(B11)-1)*1, "")*2)&"g" -> 0g | D11: =SUM(IF(ISNUMBER( SEARCH("g",B11)), LEFT(B11, LEN(B11)-1)*1, "")*3)&"g" -> 0g | E11: =SUM(IF(ISNUMBER( SEARCH("g",B11)), LEFT(B11, LEN(B11)-1)*1, "")*4)&"g" -> 0g
A12: Protein | B12: 6g | C12: =SUM(IF(ISNUMBER( SEARCH("g",B12)), LEFT(B12, LEN(B12)-1)*1, "")*2)&"g" -> 12g | D12: =SUM(IF(ISNUMBER( SEARCH("g",B12)), LEFT(B12, LEN(B12)-1)*1, "")*3)&"g" -> 18g | E12: =SUM(IF(ISNUMBER( SEARCH("g",B12)), LEFT(B12, LEN(B12)-1)*1, "")*4)&"g" -> 24g
A13: Best Foods Mayonaise
A14: Serving Size | B14: 1 Tbsp | C14: 2 Tbsp | D14: 3 TBSp
A15: Calories | B15: 90 | C15: =(B15*2) -> 180 | D15: =(B15*3) -> 270
A16: Fat | B16: 10g | C16: =SUM(IF(ISNUMBER( SEARCH("g",B16)), LEFT(B16, LEN(B16)-1)*1, "")*2)&"g" -> 20g | D16: =SUM(IF(ISNUMBER( SEARCH("g",B16)), LEFT(B16, LEN(B16)-1)*1, "")*3)&"g" -> 30g
A17: Saturated Fat | B17: 1.5g | C17: =SUM(IF(ISNUMBER( SEARCH("g",B17)), LEFT(B17, LEN(B17)-1)*1, "")*2)&"g" -> 3g | D17: =SUM(IF(ISNUMBER( SEARCH("g",B17)), LEFT(B17, LEN(B17)-1)*1, "")*3)&"g" -> 4.5g
A18: Cholesterol | B18: 5mg | C18: =SUM(IF(ISNUMBER( SEARCH("mg",B18)), LEFT(B18, LEN(B18)-2)*1, "")*2)&"mg" -> 10mg | D18: =SUM(IF(ISNUMBER( SEARCH("mg",B18)), LEFT(B18, LEN(B18)-2)*1, "")*3)&"mg" -> 15mg
A19: Sodium | B19: 95mg | C19: =SUM(IF(ISNUMBER( SEARCH("mg",B19)), LEFT(B19, LEN(B19)-2)*1, "")*2)&"mg" -> 190mg | D19: =SUM(IF(ISNUMBER( SEARCH("mg",B19)), LEFT(B19, LEN(B19)-2)*1, "")*3)&"mg" -> 285mg
A20: Carbohydrates | B20: 0g | C20: =SUM(IF(ISNUMBER( SEARCH("g",B20)), LEFT(B20, LEN(B20)-1)*1, "")*2)&"g" -> 0g | D20: =SUM(IF(ISNUMBER( SEARCH("g",B20)), LEFT(B20, LEN(B20)-1)*1, "")*3)&"g" -> 0g
A21: Fiber | B21: 0g | C21: =SUM(IF(ISNUMBER( SEARCH("g",B21)), LEFT(B21, LEN(B21)-1)*1, "")*2)&"g" -> 0g | D21: =SUM(IF(ISNUMBER( SEARCH("g",B21)), LEFT(B21, LEN(B21)-1)*1, "")*3)&"g" -> 0g
A22: Sugar | B22: 0g | C22: =SUM(IF(ISNUMBER( SEARCH("g",B22)), LEFT(B22, LEN(B22)-1)*1, "")*2)&"g" -> 0g | D22: =SUM(IF(ISNUMBER( SEARCH("g",B22)), LEFT(B22, LEN(B22)-1)*1, "")*3)&"g" -> 0g
A23: Added Sugar | B23: 0g | C23: =SUM(IF(ISNUMBER( SEARCH("g",B23)), LEFT(B23, LEN(B23)-1)*1, "")*2)&"g" -> 0g | D23: =SUM(IF(ISNUMBER( SEARCH("g",B23)), LEFT(B23, LEN(B23)-1)*1, "")*3)&"g" -> 0g
A24: Protein | B24: 0g | C24: =SUM(IF(ISNUMBER( SEARCH("g",B24)), LEFT(B24, LEN(B24)-1)*1, "")*2)&"g" -> 0g | D24: =SUM(IF(ISNUMBER( SEARCH("g",B24)), LEFT(B24, LEN(B24)-1)*1, "")*3)&"g" -> 0g
A25: Great Value Peper Jack Sliced Cheese
A26: Serving Size | B26: 1 Slice | C26: 2 Slice
A27: Calories | B27: 70 | C27: =(B27*2) -> 140
A28: Fat | B28: 6g | C28: =SUM(IF(ISNUMBER( SEARCH("g",B28)), LEFT(B28, LEN(B28)-1)*1, "")*2)&"g" -> 12g
A29: Saturated Fat | B29: 3.5g | C29: =SUM(IF(ISNUMBER( SEARCH("g",B29)), LEFT(B29, LEN(B29)-1)*1, "")*2)&"g" -> 7g
A30: Cholesterol | B30: 20mg | C30: =SUM(IF(ISNUMBER( SEARCH("mg",B30)), LEFT(B30, LEN(B30)-2)*1, "")*2)&"mg" -> 40mg
A31: Sodium | B31: 125 mg | C31: =SUM(IF(ISNUMBER( SEARCH("mg",B31)), LEFT(B31, LEN(B31)-2)*1, "")*2)&"mg" -> 250mg
A32: Carbohydrates | B32: 0g | C32: =SUM(IF(ISNUMBER( SEARCH("g",B32)), LEFT(B32, LEN(B32)-1)*1, "")*2)&"g" -> 0g
A33: Fiber | B33: 0g | C33: =SUM(IF(ISNUMBER( SEARCH("g",B33)), LEFT(B33, LEN(B33)-1)*1, "")*2)&"g" -> 0g
A34: Sugar | B34: 0g | C34: =SUM(IF(ISNUMBER( SEARCH("g",B34)), LEFT(B34, LEN(B34)-1)*1, "")*2)&"g" -> 0g
A35: Added Sugar | B35: 0g | C35: =SUM(IF(ISNUMBER( SEARCH("g",B35)), LEFT(B35, LEN(B35)-1)*1, "")*2)&"g" -> 0g
A36: Protein | B36: 5g | C36: =SUM(IF(ISNUMBER( SEARCH("g",B36)), LEFT(B36, LEN(B36)-1)*1, "")*2)&"g" -> 10g
A37: Great Value Sliced Swiss Cheese
A38: Serving Size | B38: 1 slice | C38: 2 Slice
A39: Calories | B39: 70 | C39: =(B39*2) -> 140
A40: Fat | B40: 6g | C40: =SUM(IF(ISNUMBER( SEARCH("g",B40)), LEFT(B40, LEN(B40)-1)*1, "")*2)&"g" -> 12g
...

Sheet Carbohydrates
A1: Franz Whole Wheat Bread
A2: Serving Size | B2: 1 slice | C2: 2 slices | D2: 3 slices | E2: 4 slices
A3: Calories | B3: 80 | C3: =(B3*2) -> 160 | D3: =B3*3 -> 240 | E3: =(B3*4) -> 320
A4: Fat | B4: 1g | C4: =SUM(IF(ISNUMBER( SEARCH("g",B4)), LEFT(B4, LEN(B4)-1)*1, "")*2)&"g" -> 2g | D4: =SUM(IF(ISNUMBER( SEARCH("g",B4)), LEFT(B4, LEN(B4)-1)*1, "")*3)&"g" -> 3g | E4: =SUM(IF(ISNUMBER( SEARCH("g",B4)), LEFT(B4, LEN(B4)-1)*1, "")*4)&"g" -> 4g
A5: Saturated Fat | B5: 0g | C5: =SUM(IF(ISNUMBER( SEARCH("g",B5)), LEFT(B5, LEN(B5)-1)*1, "")*2)&"g" -> 0g | D5: =SUM(IF(ISNUMBER( SEARCH("g",B5)), LEFT(B5, LEN(B5)-1)*1, "")*3)&"g" -> 0g | E5: =SUM(IF(ISNUMBER( SEARCH("g",B5)), LEFT(B5, LEN(B5)-1)*1, "")*4)&"g" -> 0g
A6: Cholesterol | B6: 0mg | C6: =SUM(IF(ISNUMBER( SEARCH("mg",B6)), LEFT(B6, LEN(B6)-2)*1, "")*2)&"mg" -> 0mg | D6: =SUM(IF(ISNUMBER( SEARCH("mg",C6)), LEFT(C6, LEN(C6)-2)*1, "")+(SUM(IF(ISNUMBER( SEARCH("mg",B6)), LEFT(B6, LEN(B6)-2)*1, ""))))&"mg" -> 0mg | E6: =SUM(IF(ISNUMBER( SEARCH("mg",B6)), LEFT(B6, LEN(B6)-2)*1, "")*4)&"mg" -> 0mg
A7: Sodium | B7: 150mg | C7: =SUM(IF(ISNUMBER( SEARCH("mg",B7)), LEFT(B7, LEN(B7)-2)*1, "")*2)&"mg" -> 300mg | D7: =SUM(IF(ISNUMBER( SEARCH("mg",B7)), LEFT(B7, LEN(B7)-2)*1, "")*3)&"mg" -> 450mg | E7: =SUM(IF(ISNUMBER( SEARCH("mg",B7)), LEFT(B7, LEN(B7)-2)*1, "")*4)&"mg" -> 600mg
A8: Carbohydrates | B8: 15g | C8: =SUM(IF(ISNUMBER( SEARCH("g",B8)), LEFT(B8, LEN(B8)-1)*1, "")*2)&"g" -> 30g | D8: =SUM(IF(ISNUMBER( SEARCH("g",B8)), LEFT(B8, LEN(B8)-1)*1, "")*3)&"g" -> 45g | E8: =SUM(IF(ISNUMBER( SEARCH("g",B8)), LEFT(B8, LEN(B8)-1)*1, "")*4)&"g" -> 60g
A9: Fiber | B9: 2g | C9: =SUM(IF(ISNUMBER( SEARCH("g",B9)), LEFT(B9, LEN(B9)-1)*1, "")*2)&"g" -> 4g | D9: =SUM(IF(ISNUMBER( SEARCH("g",B9)), LEFT(B9, LEN(B9)-1)*1, "")*3)&"g" -> 6g | E9: =SUM(IF(ISNUMBER( SEARCH("g",B9)), LEFT(B9, LEN(B9)-1)*1, "")*4)&"g" -> 8g
A10: Sugar | B10: 1g | C10: =SUM(IF(ISNUMBER( SEARCH("g",B10)), LEFT(B10, LEN(B10)-1)*1, "")*2)&"g" -> 2g | D10: =SUM(IF(ISNUMBER( SEARCH("g",B10)), LEFT(B10, LEN(B10)-1)*1, "")*3)&"g" -> 3g | E10: =SUM(IF(ISNUMBER( SEARCH("g",B10)), LEFT(B10, LEN(B10)-1)*1, "")*4)&"g" -> 4g
A11: Added Sugar | B11: 1g | C11: =SUM(IF(ISNUMBER( SEARCH("g",B11)), LEFT(B11, LEN(B11)-1)*1, "")*2)&"g" -> 2g | D11: =SUM(IF(ISNUMBER( SEARCH("g",B11)), LEFT(B11, LEN(B11)-1)*1, "")*3)&"g" -> 3g | E11: =SUM(IF(ISNUMBER( SEARCH("g",B11)), LEFT(B11, LEN(B11)-1)*1, "")*4)&"g" -> 4g
A12: Protein | B12: 4g | C12: =SUM(IF(ISNUMBER( SEARCH("g",B12)), LEFT(B12, LEN(B12)-1)*1, "")*2)&"g" -> 8g | D12: =SUM(IF(ISNUMBER( SEARCH("g",B12)), LEFT(B12, LEN(B12)-1)*1, "")*3)&"g" -> 12g | E12: =SUM(IF(ISNUMBER( SEARCH("g",B12)), LEFT(B12, LEN(B12)-1)*1, "")*4)&"g" -> 16g
A13: Franz Cinnamon Raisin Bagels
A14: Serving Size | B14: 1/2 bagel | C14: 1 bagel
A15: Calories | B15: 115 | C15: =(B15*2) -> 230
A16: Fat | B16: 1g | C16: =SUM(IF(ISNUMBER( SEARCH("g",B16)), LEFT(B16, LEN(B16)-1)*1, "")*2)&"g" -> 2g
A17: Saturated Fat | B17: 0g | C17: =SUM(IF(ISNUMBER( SEARCH("g",B17)), LEFT(B17, LEN(B17)-1)*1, "")*2)&"g" -> 0g
A18: Cholesterol | B18: 0mg | C18: =SUM(IF(ISNUMBER( SEARCH("mg",B18)), LEFT(B18, LEN(B18)-2)*1, "")*2)&"mg" -> 0mg
A19: Sodium | B19: 160mg | C19: =SUM(IF(ISNUMBER( SEARCH("mg",B19)), LEFT(B19, LEN(B19)-2)*1, "")*2)&"mg" -> 320mg
A20: Carbohydrates | B20: 23g | C20: =SUM(IF(ISNUMBER( SEARCH("g",B20)), LEFT(B20, LEN(B20)-1)*1, "")*2)&"g" -> 46g
A21: Fiber | B21: 1g | C21: =SUM(IF(ISNUMBER( SEARCH("g",B21)), LEFT(B21, LEN(B21)-1)*1, "")*2)&"g" -> 2g
A22: Sugar | B22: 5g | C22: =SUM(IF(ISNUMBER( SEARCH("g",B22)), LEFT(B22, LEN(B22)-1)*1, "")*2)&"g" -> 10g
A23: Added Sugar | B23: 3g | C23: =SUM(IF(ISNUMBER( SEARCH("g",B23)), LEFT(B23, LEN(B23)-1)*1, "")*2)&"g" -> 6g
A24: Protein | B24: 3.5g | C24: =SUM(IF(ISNUMBER( SEARCH("g",B24)), LEFT(B24, LEN(B24)-1)*1, "")*2)&"g" -> 7g
A25: French Toast
A26: Serving Size | B26: 3 Slices | C26: 6 Slices | D26: 12 Slices
A27: Calories | B27: =D27*0.25 -> 320 | C27: =ROUNDUP(SUM(D27/2),2) -> 640 | D27: 1280
A28: Fat | B28: =ROUNDUP(SUM(IF(ISNUMBER( SEARCH("g",D28)), LEFT(D28, LEN(D28)-1)*1, "")*0.25),2)&"g" -> 7g | C28: =ROUNDUP(SUM(IF(ISNUMBER( SEARCH("g",D28)), LEFT(D28, LEN(D28)-1)*1, "")*0.5),2)&"g" -> 14g | D28: 28g
A29: Saturated Fat | B29: =ROUNDUP(SUM(IF(ISNUMBER( SEARCH("g",D29)), LEFT(D29, LEN(D29)-1)*1, "")*0.25),2)&"g" -> 2.5g | C29: =ROUNDUP(SUM(IF(ISNUMBER( SEARCH("g",D29)), LEFT(D29, LEN(D29)-1)*1, "")*0.5),2)&"g" -> 5g | D29: 10g
A30: Cholesterol | B30: =ROUNDUP(SUM(IF(ISNUMBER( SEARCH("mg",D30)), LEFT(D30, LEN(D30)-2)*1, "")*0.25),2)&"mg" -> 17.5mg | C30: =ROUNDUP(SUM(IF(ISNUMBER( SEARCH("mg",D30)), LEFT(D30, LEN(D30)-2)*1, "")*0.5),2)&"mg" -> 35mg | D30: 70mg
A31: Sodium | B31: =ROUNDUP(SUM(IF(ISNUMBER( SEARCH("mg",D31)), LEFT(D31, LEN(D31)-2)*1, "")*0.25),2)&"mg" -> 516mg | C31: =ROUNDUP(SUM(IF(ISNUMBER( SEARCH("mg",D31)), LEFT(D31, LEN(D31)-2)*1, "")*0.5),2)&"mg" -> 1032mg | D31: 2,064mg
A32: Carbohydrates | B32: =ROUNDUP(SUM(IF(ISNUMBER( SEARCH("g",D32)), LEFT(D32, LEN(D32)-1)*1, "")*0.25),2)&"g" -> 51.5g | C32: =ROUNDUP(SUM(IF(ISNUMBER( SEARCH("g",D32)), LEFT(D32, LEN(D32)-1)*1, "")*0.5),2)&"g" -> 103g | D32: 206g
A33: Fiber | B33: =ROUNDUP(SUM(IF(ISNUMBER( SEARCH("g",D33)), LEFT(D33, LEN(D33)-1)*1, "")*0.25),2)&"g" -> 6g | C33: =ROUNDUP(SUM(IF(ISNUMBER( SEARCH("g",D33)), LEFT(D33, LEN(D33)-1)*1, "")*0.5),2)&"g" -> 12g | D33: 24g
A34: Sugars | B34: =ROUNDUP(SUM(IF(ISNUMBER( SEARCH("g",D34)), LEFT(D34, LEN(D34)-1)*1, "")*0.25),2)&"g" -> 9g | C34: =ROUNDUP(SUM(IF(ISNUMBER( SEARCH("g",D34)), LEFT(D34, LEN(D34)-1)*1, "")*0.5),2)&"g" -> 18g | D34: 36g
A35: Added Sugar | B35: =ROUNDUP(SUM(IF(ISNUMBER( SEARCH("g",D35)), LEFT(D35, LEN(D35)-1)*1, "")*0.25),2)&"g" -> 3g | C35: =ROUNDUP(SUM(IF(ISNUMBER( SEARCH("g",D35)), LEFT(D35, LEN(D35)-1)*1, "")*0.5),2)&"g" -> 6g | D35: 12g
A36: Protein | B36: =ROUNDUP(SUM(IF(ISNUMBER( SEARCH("g",D36)), LEFT(D36, LEN(D36)-1)*1, "")*0.25),2)&"g" -> 16.5g | C36: =ROUNDUP(SUM(IF(ISNUMBER( SEARCH("g",D36)), LEFT(D36, LEN(D36)-1)*1, "")*0.5),2)&"g" -> 33g | D36: 66g
A37: Franz Hot Dog Buns
A38: Serving Size | B38: 1 Bun | C38: 2 bun | D38: 3 buns
A39: Calories | B39: 120 | C39: =(B39*2) -> 240 | D39: =(B39*3) -> 360
A40: Fat | B40: 1.5g | C40: =SUM(IF(ISNUMBER( SEARCH("g",B40)), LEFT(B40, LEN(B40)-1)*1, "")*2)&"g" -> 3g | D40: =SUM(IF(ISNUMBER( SEARCH("g",B40)), LEFT(B40, LEN(B40)-1)*1, "")*3)&"g" -> 4.5g
...

Sheet BAD
A1: Taco Bell Sausage Breakfast Crunchwrap
A2: Serving Size | B2: 1 Crunchwrap
A3: Calories | B3: 670
A4: Fat | B4: 41g
A5: Saturated Fat | B5: 12g
A6: Cholesterol | B6: 140mg
A7: Sodium | B7: 1,270mg
A8: Carbohydrates | B8: 50g
A9: Fiber | B9: 4g
A10: Sugar | B10: 3g
A11: Added Sugar | B11: 0g
A12: Protein | B12: 21g
A13: Taco Bell Chicken Chalupa
A14: Serving Size | B14: 1 Chalupa
A15: Calories | B15: 371 | C15: =B15*2 -> 742
A16: Fat | B16: 15g | C16: =SUM(IF(ISNUMBER( SEARCH("g",B16)), LEFT(B16, LEN(B16)-1)*1, "")*2)&"g" -> 30g
A17: Saturated Fat | B17: 3.5g | C17: =SUM(IF(ISNUMBER( SEARCH("g",B17)), LEFT(B17, LEN(B17)-1)*1, "")*2)&"g" -> 7g
A18: Cholesterol | B18: 35mg | C18: =SUM(IF(ISNUMBER( SEARCH("mg",B18)), LEFT(B18, LEN(B18)-2)*1, "")+(SUM(IF(ISNUMBER( SEARCH("mg",B18)), LEFT(B18, LEN(B18)-2)*1, ""))))&"mg" -> 70mg
A19: Sodium | B19: 570mg | C19: =SUM(IF(ISNUMBER( SEARCH("mg",B19)), LEFT(B19, LEN(B19)-2)*1, "")+(SUM(IF(ISNUMBER( SEARCH("mg",B19)), LEFT(B19, LEN(B19)-2)*1, ""))))&"mg" -> 1140mg
A20: Carbohydrates | B20: 31g | C20: =SUM(IF(ISNUMBER( SEARCH("g",B20)), LEFT(B20, LEN(B20)-1)*1, "")*2)&"g" -> 62g
A21: Fiber | B21: 2g | C21: =SUM(IF(ISNUMBER( SEARCH("g",B21)), LEFT(B21, LEN(B21)-1)*1, "")*2)&"g" -> 4g
A22: Sugar | B22: 3g | C22: =SUM(IF(ISNUMBER( SEARCH("g",B22)), LEFT(B22, LEN(B22)-1)*1, "")*2)&"g" -> 6g
A23: Added Sugar | B23: 0g | C23: =SUM(IF(ISNUMBER( SEARCH("g",B23)), LEFT(B23, LEN(B23)-1)*1, "")*2)&"g" -> 0g
A24: Protein | B24: 16g | C24: =SUM(IF(ISNUMBER( SEARCH("g",B24)), LEFT(B24, LEN(B24)-1)*1, "")*2)&"g" -> 32g
A25: Taco Bell Beefy 5-Layer Burrito
A26: Serving Size | B26: 1 Burrito | C26: 2 Burritos
A27: Calories | B27: 490 | C27: =(B27*2) -> 980
A28: Fat | B28: 18g | C28: =SUM(IF(ISNUMBER( SEARCH("g",B28)), LEFT(B28, LEN(B28)-1)*1, "")*2)&"g" -> 36g
A29: Saturated Fat | B29: 7g | C29: =SUM(IF(ISNUMBER( SEARCH("g",B29)), LEFT(B29, LEN(B29)-1)*1, "")*2)&"g" -> 14g
A30: Cholesterol | B30: 30mg | C30: =SUM(IF(ISNUMBER( SEARCH("mg",B30)), LEFT(B30, LEN(B30)-2)*1, "")+(SUM(IF(ISNUMBER( SEARCH("mg",B30)), LEFT(B30, LEN(B30)-2)*1, ""))))&"mg" -> 60mg
A31: Sodium | B31: 1,250mg | C31: =SUM(IF(ISNUMBER( SEARCH("mg",B31)), LEFT(B31, LEN(B31)-2)*1, "")+(SUM(IF(ISNUMBER( SEARCH("mg",B31)), LEFT(B31, LEN(B31)-2)*1, ""))))&"mg" -> 2500mg
A32: Carbohydrates | B32: 63g | C32: =SUM(IF(ISNUMBER( SEARCH("g",B32)), LEFT(B32, LEN(B32)-1)*1, "")*2)&"g" -> 126g
A33: Fiber | B33: 9g | C33: =SUM(IF(ISNUMBER( SEARCH("g",B33)), LEFT(B33, LEN(B33)-1)*1, "")*2)&"g" -> 18g
A34: Sugar | B34: 5g | C34: =SUM(IF(ISNUMBER( SEARCH("g",B34)), LEFT(B34, LEN(B34)-1)*1, "")*2)&"g" -> 10g
A35: Added Sugar | B35: 0g | C35: =SUM(IF(ISNUMBER( SEARCH("g",B35)), LEFT(B35, LEN(B35)-1)*1, "")*2)&"g" -> 0g
A36: Protein | B36: 18g | C36: =SUM(IF(ISNUMBER( SEARCH("g",B36)), LEFT(B36, LEN(B36)-1)*1, "")*2)&"g" -> 36g
A37: Taco Bell Burrito Supreme
A38: Serving Size | B38: 1 Burrito | C38: 2 Burritos
A39: Calories | B39: 390 | C39: =(B39*2) -> 780
A40: Fat | B40: 14g | C40: =SUM(IF(ISNUMBER( SEARCH("g",B40)), LEFT(B40, LEN(B40)-1)*1, "")*2)&"g" -> 28g
...

Sheet Every plate means
A1: Sweet and Tangy Meatballs with Roasted Zucchini and Garlic Mashed Potatoes
A2: Serving Size | B2: 1 serving
A3: Calories | B3: 620
A4: Fat | B4: 30g
A5: Saturated Fat | B5: 13g
A6: Cholesterol | B6: 100mg
A7: Sodium | B7: 620mg
A8: Carbohydrates | B8: 61g
A9: Fiber | B9: 5g
A10: Sugar | B10: 24g
A11: Added Sugar | B11: 0g
A12: Protein | B12: 28g
B14: 1 meal
B15: 690cal
B16: 36g
B17: 15g
B18: 160g
B19: 1,270mg
B20: 51g
B21: 5g
B22: 9g
B23: 0g
B24: 37g

Sheet Combos
A1: Ham Sandwhich on Wheat | B1: Serving Size | C1: Calories | D1: Fat | E1: Saturated Fat | F1: Cholesterol | G1: Sodium | H1: Carbohydrates | I1: Fiber | J1: Sugar | K1: Added Sugar | L1: Protein
A2: 1 Sandwhich | B2: Total | C2: =SUM(C3:C6) -> 358 | D2: {=SUM(IF(ISNUMBER( SEARCH("g",D3:D6)), LEFT(D3:D6, LEN(D3:D6)-1)*1, ""))&"g"} -> 19.5g | E2: {=SUM(IF(ISNUMBER( SEARCH("g",E3:E6)), LEFT(E3:E6, LEN(E3:E6)-1)*1, ""))&"g"} -> 5g | F2: {=SUM(IF(ISNUMBER( SEARCH("mg",F3:F6)), LEFT(F3:F6, LEN(F3:F6)-2)*1, ""))&"mg"} -> 44mg | G2: {=SUM(IF(ISNUMBER( SEARCH("mg",G3:G6)), LEFT(G3:G6, LEN(G3:G6)-2)*1, ""))&"mg"} -> 933mg | H2: {=SUM(IF(ISNUMBER( SEARCH("g",H3:H6)), LEFT(H3:H6, LEN(H3:H6)-1)*1, ""))&"g"} -> 31.5g | I2: {=SUM(IF(ISNUMBER( SEARCH("g",I3:I6)), LEFT(I3:I6, LEN(I3:I6)-1)*1, ""))&"g"} -> 4g | J2: {=SUM(IF(ISNUMBER( SEARCH("g",J3:J6)), LEFT(J3:J6, LEN(J3:J6)-1)*1, ""))&"g"} -> 3.5g | K2: {=SUM(IF(ISNUMBER( SEARCH("g",K3:K6)), LEFT(K3:K6, LEN(K3:K6)-1)*1, ""))&"g"} -> 2g | L2: {=SUM(IF(ISNUMBER( SEARCH("g",L3:L6)), LEFT(L3:L6, LEN(L3:L6)-1)*1, ""))&"g"} -> 19g
B3: 3 slices of Ham | C3: 38 | D3: 1.5g | E3: 0g | F3: 19mg | G3: 413mg | H3: 1.5g | I3: 0g | J3: 1.5g | K3: 0g | L3: 6g
B4: 1 slice of Pepper Jack Cheese | C4: 70 | D4: 6g | E4: 3.5g | F4: 20mg | G4: 125mg | H4: 0g | I4: 0g | J4: 0g | K4: 0g | L4: 5g
B5: 1 Tbsp Best Foods Mayonaise | C5: 90 | D5: 10g | E5: 1.5g | F5: 5mg | G5: 95mg | H5: 0g | I5: 0g | J5: 0g | K5: 0g | L5: 0g
B6: 2 Slices Franz Whole Wheat Bread | C6: 160 | D6: 2g | E6: 0g | F6: 0mg | G6: 300mg | H6: 30g | I6: 4g | J6: 2g | K6: 2g | L6: 8g
A7: 2 Sandwhiches | B7: Total | C7: =SUM(C8:C11) -> 716 | D7: {=SUM(IF(ISNUMBER( SEARCH("g",D8:D11)), LEFT(D8:D11, LEN(D8:D11)-1)*1, ""))&"g"} -> 39g | E7: {=SUM(IF(ISNUMBER( SEARCH("g",E8:E11)), LEFT(E8:E11, LEN(E8:E11)-1)*1, ""))&"g"} -> 8.5g | F7: {=SUM(IF(ISNUMBER( SEARCH("mg",F8:F11)), LEFT(F8:F11, LEN(F8:F11)-2)*1, ""))&"mg"} -> 88mg | G7: {=SUM(IF(ISNUMBER( SEARCH("mg",G8:G11)), LEFT(G8:G11, LEN(G8:G11)-2)*1, ""))&"mg"} -> 1866mg | H7: {=SUM(IF(ISNUMBER( SEARCH("g",H8:H11)), LEFT(H8:H11, LEN(H8:H11)-1)*1, ""))&"g"} -> 63g | I7: {=SUM(IF(ISNUMBER( SEARCH("g",I8:I11)), LEFT(I8:I11, LEN(I8:I11)-1)*1, ""))&"g"} -> 8g | J7: {=SUM(IF(ISNUMBER( SEARCH("g",J8:J11)), LEFT(J8:J11, LEN(J8:J11)-1)*1, ""))&"g"} -> 7g | K7: {=SUM(IF(ISNUMBER( SEARCH("g",K8:K11)), LEFT(K8:K11, LEN(K8:K11)-1)*1, ""))&"g"} -> 4g | L7: {=SUM(IF(ISNUMBER( SEARCH("g",L8:L11)), LEFT(L8:L11, LEN(L8:L11)-1)*1, ""))&"g"} -> 38g
B8: 6 slices of Ham | C8: =SUM(C3*2) -> 76 | D8: 3g | E8: 0g | F8: 38mg | G8: 826mg | H8: 3g | I8: 0g | J8: 3g | K8: 0g | L8: 12g
B9: 6 slice of Pepper jack Cheese | C9: =SUM(C4*2) -> 140 | D9: 12g | E9: 7g | F9: 40mg | G9: 250mg | H9: 0g | I9: 0g | J9: 0g | K9: 0g | L9: 10g
B10: 2 Tbsp Best Foods Mayonaise | C10: =SUM(C5*2) -> 180 | D10: 20g | E10: 1.5g | F10: 10mg | G10: 190mg | H10: 0g | I10: 0g | J10: 0g | K10: 0g | L10: 0g
B11: 2 Slices Franz Whole Wheat Bread | C11: =SUM(C6*2) -> 320 | D11: 4g | E11: 0g | F11: 0mg | G11: 600mg | H11: 60g | I11: 8g | J11: 4g | K11: 4g | L11: 16g
A12: Peanut Butter and Jelly Sandwhiches | B12: Serving Size | C12: Calories | D12: Fat | E12: Saturated Fat | F12: Cholesterol | G12: Sodium | H12: Carbohydrates | I12: Fiber | J12: Sugar | K12: Added Sugar | L12: Protein
A13: 1 Sandwhich | B13: Total | C13: =SUM(C14:C16) -> 290 | D13: {=SUM(IF(ISNUMBER( SEARCH("g",D14:D16)), LEFT(D14:D16, LEN(D14:D16)-1)*1, ""))&"g"} -> 10g | E13: {=SUM(IF(ISNUMBER( SEARCH("g",E14:E16)), LEFT(E14:E16, LEN(E14:E16)-1)*1, ""))&"g"} -> 2g | F13: {=SUM(IF(ISNUMBER( SEARCH("mg",F14:F16)), LEFT(F14:F16, LEN(F14:F16)-2)*1, ""))&"mg"} -> 0mg | G13: {=SUM(IF(ISNUMBER( SEARCH("mg",G14:G16)), LEFT(G14:G16, LEN(G14:G16)-2)*1, ""))&"mg"} -> 370mg | H13: {=SUM(IF(ISNUMBER( SEARCH("g",H14:H16)), LEFT(H14:H16, LEN(H14:H16)-1)*1, ""))&"g"} -> 43g | I13: {=SUM(IF(ISNUMBER( SEARCH("g",I14:I16)), LEFT(I14:I16, LEN(I14:I16)-1)*1, ""))&"g"} -> 5g | J13: {=SUM(IF(ISNUMBER( SEARCH("g",J14:J16)), LEFT(J14:J16, LEN(J14:J16)-1)*1, ""))&"g"} -> 13g | K13: {=SUM(IF(ISNUMBER( SEARCH("g",K14:K16)), LEFT(K14:K16, LEN(K14:K16)-1)*1, ""))&"g"} -> 11g | L13: {=SUM(IF(ISNUMBER( SEARCH("g",L14:L16)), LEFT(L14:L16, LEN(L14:L16)-1)*1, ""))&"g"} -> 11.5g
B14: 1 Tbsp Peanut Butter | C14: 95 | D14: 8g | E14: 2g | F14: 0mg | G14: 70mg | H14: 4g | I14: 1g | J14: 2g | K14: 1g | L14: 3.5g
B15: 1 Tbsp Kirkland Organic Starwberry Spread | C15: 35 | D15: 0g | E15: 0g | F15: 0mg | G15: 0mg | H15: 9g | I15: 0g | J15: 9g | K15: 8g | L15: 0g
B16: 2 Slices Franz Whole Wheat Bread | C16: 160 | D16: 2g | E16: 0g | F16: 0mg | G16: 300mg | H16: 30g | I16: 4g | J16: 2g | K16: 2g | L16: 8g
A17: 2 Sandwhiches | B17: Total | C17: =SUM(C18:C20) -> 580 | D17: {=SUM(IF(ISNUMBER( SEARCH("g",D18:D20)), LEFT(D18:D20, LEN(D18:D20)-1)*1, ""))&"g"} -> 20g | E17: {=SUM(IF(ISNUMBER( SEARCH("g",E18:E20)), LEFT(E18:E20, LEN(E18:E20)-1)*1, ""))&"g"} -> 4g | F17: {=SUM(IF(ISNUMBER( SEARCH("mg",F18:F20)), LEFT(F18:F20, LEN(F18:F20)-2)*1, ""))&"mg"} -> 0mg | G17: {=SUM(IF(ISNUMBER( SEARCH("mg",G18:G20)), LEFT(G18:G20, LEN(G18:G20)-2)*1, ""))&"mg"} -> 770mg | H17: {=SUM(IF(ISNUMBER( SEARCH("g",H18:H20)), LEFT(H18:H20, LEN(H18:H20)-1)*1, ""))&"g"} -> 86g | I17: {=SUM(IF(ISNUMBER( SEARCH("g",I18:I20)), LEFT(I18:I20, LEN(I18:I20)-1)*1, ""))&"g"} -> 10g | J17: {=SUM(IF(ISNUMBER( SEARCH("g",J18:J20)), LEFT(J18:J20, LEN(J18:J20)-1)*1, ""))&"g"} -> 27g | K17: {=SUM(IF(ISNUMBER( SEARCH("g",K18:K20)), LEFT(K18:K20, LEN(K18:K20)-1)*1, ""))&"g"} -> 22g | L17: {=SUM(IF(ISNUMBER( SEARCH("g",L18:L20)), LEFT(L18:L20, LEN(L18:L20)-1)*1, ""))&"g"} -> 23g
B18: 2 Tbsp Peanut Butter | C18: 190 | D18: 16g | E18: 4g | F18: 0mg | G18: 170mg | H18: 8g | I18: 2g | J18: 4g | K18: 2g | L18: 7g
B19: 2 Tbsp Kirkland Organic Starwberry Spread | C19: 70 | D19: 0g | E19: 0g | F19: 0mg | G19: 0mg | H19: 18g | I19: 0g | J19: 19g | K19: 16g | L19: 0g
B20: 4 Slices Franz Whole Wheat Bread | C20: 320 | D20: 4g | E20: 0g | F20: 0mg | G20: 600mg | H20: 60g | I20: 8g | J20: 4g | K20: 4g | L20: 16g
A21: Hardboiled Egg Sandwhiches | B21: Serving Size | C21: Calories | D21: Fat | E21: Saturated Fat | F21: Cholesterol | G21: Sodium | H21: Carbohydrates | I21: Fiber | J21: Sugar | K21: Added Sugar | L21: Protein
